Workbook

Sheet PTKP & TARIF
A2: PTKP Update Tahun 2015 | D2: KATEGORI TER
A3: STATUS | B3: PTKP SETAHUN | D3: STATUS | E3: PTKP SETAHUN | H3: YA
A4: TK0 | B4: 54000000 | D4: TK0 | E4: TER A | H4: TIDAK
A5: TK1 | B5: =+B4+4500000 -> 58500000 | D5: TK1 | E5: TER A
A6: TK2 | B6: =+B5+4500000 -> 63000000 | D6: K0 | E6: TER A
A7: TK3 | B7: =+B6+4500000 -> 67500000 | D7: TK2 | E7: TER B
A8: K0 | B8: 58500000 | D8: TK3 | E8: TER B
A9: K1 | B9: 63000000 | D9: K1 | E9: TER B
A10: K2 | B10: 67500000 | D10: K2 | E10: TER B
A11: K3 | B11: 72000000 | D11: K3 | E11: TER C
A14: Tarif PPh Pasal 17 Terbaru
A15: TARIF | B15: PENGHASILAN BRUTO
A16: 0.05 | B16: <= 60.000.000
A17: 0.15 | B17: >60.000.000 s.d 250.000.000
A18: 0.25 | B18: >250.000.000 s.d 500.000.000
A19: 0.3 | B19: > 500.000.000 s.d. 5M
A20: 0.35 | B20: > 5M

Sheet TER
A1: PENERAPAN PERHITUNGAN PPh 21 SESUAI PP NO. 58 TAHUN 2023
A3: KATEGORI A (TK0/TK1/K0) | F3: KATEGORI B (TK2/TK3/K1/K2) | K3: KATEGORI C (K3) | P3: HARIAN
A4: Range | D4: Tarif | F4: Range | I4: Tarif | K4: Range | N4: Tarif | P4: Range | S4: Tarif
A5: 0 | B5: s.d. | C5: 5400000 | D5: 0 | F5: 0 | G5: s.d. | H5: 6200000 | I5: 0 | K5: 0 | L5: s.d. | M5: 6600000 | N5: 0 | P5: 0 | Q5: s.d. | R5: 450000 | S5: 0
A6: 5400001 | B6: s.d. | C6: 5650000 | D6: 0.0025 | F6: 6200001 | G6: s.d. | H6: 6500000 | I6: 0.0025 | K6: 6600001 | L6: s.d. | M6: 6950000 | N6: 0.0025 | P6: 450000 | Q6: s.d. | R6: 2500000 | S6: 0.005
A7: 5650001 | B7: s.d. | C7: 5950000 | D7: 0.005 | F7: 6500001 | G7: s.d. | H7: 6850000 | I7: 0.005 | K7: 6950001 | L7: s.d. | M7: 7350000 | N7: 0.005
A8: 5950001 | B8: s.d. | C8: 6300000 | D8: 0.0075 | F8: 6850001 | G8: s.d. | H8: 7300000 | I8: 0.0075 | K8: 7350001 | L8: s.d. | M8: 7800000 | N8: 0.0075
A9: 6300001 | B9: s.d. | C9: 6750000 | D9: 0.01 | F9: 7300001 | G9: s.d. | H9: 9200000 | I9: 0.01 | K9: 7800001 | L9: s.d. | M9: 8850000 | N9: 0.01
A10: 6750001 | B10: s.d. | C10: 7500000 | D10: 0.0125 | F10: 9200001 | G10: s.d. | H10: 10750000 | I10: 0.015 | K10: 8850001 | L10: s.d. | M10: 9800000 | N10: 0.0125
A11: 7500001 | B11: s.d. | C11: 8550000 | D11: 0.015 | F11: 10750001 | G11: s.d. | H11: 11250000 | I11: 0.02 | K11: 9800001 | L11: s.d. | M11: 10950000 | N11: 0.015
A12: 8550001 | B12: s.d. | C12: 9650000 | D12: 0.0175 | F12: 11250001 | G12: s.d. | H12: 11600000 | I12: 0.025 | K12: 10950001 | L12: s.d. | M12: 11200000 | N12: 0.0175
A13: 9650001 | B13: s.d. | C13: 10050000 | D13: 0.02 | F13: 11600001 | G13: s.d. | H13: 12600000 | I13: 0.03 | K13: 11200001 | L13: s.d. | M13: 12050000 | N13: 0.02
A14: 10050001 | B14: s.d. | C14: 10350000 | D14: 0.0225 | F14: 12600001 | G14: s.d. | H14: 13600000 | I14: 0.04 | K14: 12050001 | L14: s.d. | M14: 12950000 | N14: 0.03
A15: 10350001 | B15: s.d. | C15: 10700000 | D15: 0.025 | F15: 13600001 | G15: s.d. | H15: 14950000 | I15: 0.05 | K15: 12950001 | L15: s.d. | M15: 14150000 | N15: 0.04
A16: 10700001 | B16: s.d. | C16: 11050000 | D16: 0.03 | F16: 14950001 | G16: s.d. | H16: 16400000 | I16: 0.06 | K16: 14150001 | L16: s.d. | M16: 15550000 | N16: 0.05
A17: 11050001 | B17: s.d. | C17: 11600000 | D17: 0.035 | F17: 16400001 | G17: s.d. | H17: 18450000 | I17: 0.07 | K17: 15550001 | L17: s.d. | M17: 17050000 | N17: 0.06
A18: 11600001 | B18: s.d. | C18: 12500000 | D18: 0.04 | F18: 18450001 | G18: s.d. | H18: 21850000 | I18: 0.08 | K18: 17050001 | L18: s.d. | M18: 19500000 | N18: 0.07
... A43: 337000001 | B43: s.d. | C43: 454000000 | D43: 0.29 | F43: 957000001 | G43: s.d. | H43: 1405000000 | I43: 0.33 | K43: 709000001 | L43: s.d. | M43: 965000000 | N43: 0.32
A44: 454000001 | B44: s.d. | C44: 550000000 | D44: 0.3 | F44: 1405000001 | G44: s.d. | H44: ~ | I44: 0.34 | K44: 965000001 | L44: s.d. | M44: 1419000000 | N44: 0.33
A45: 550000001 | B45: s.d. | C45: 695000000 | D45: 0.31 | K45: 1419000001 | L45: s.d. | M45: ~ | N45: 0.34
A46: 695000001 | B46: s.d. | C46: 910000000 | D46: 0.32
A47: 910000001 | B47: s.d. | C47: 1400000000 | D47: 0.33
A48: 1400000001 | B48: s.d. | C48: ~ | D48: 0.34
A57: 5300000 | C57: =VLOOKUP(A57,$A$5:$D$48,4,TRUE) -> 0
A58: 5600000 | C58: =VLOOKUP(A58,$A$5:$D$48,4,TRUE) -> 0.0025
A59: 6000000 | C59: =VLOOKUP(A59,$A$5:$D$48,4,TRUE) -> 0.0075
A60: 7500000 | C60: =VLOOKUP(A60,$A$5:$D$48,4,TRUE) -> 0.0125
A61: 7200000 | C61: =VLOOKUP(A61,$A$5:$D$48,4,TRUE) -> 0.0125
A62: 6500000 | C62: =VLOOKUP(A62,$A$5:$D$48,4,TRUE) -> 0.01

Sheet Data Gaji
A1: PT. X
A2: PERHITUNGAN PPh 21 BULANAN (TER PP 58 Tahun 2023)
A3: BULAN JANUARI-DESEMBER 2024 | N3: JANUARI | AN3: FEBRUARI | BN3: MARET | CN3: APRIL | DN3: MEI | EN3: JUNI | FN3: JULI | GN3: AGUSTUS | HN3: SEPTEMBER | IN3: OKTOBER | JN3: NOVEMBER | KN3: DESEMBER
A4: NO. | B4: NIP | C4: NIK (KTP) | D4: BULAN MASUK KERJA | E4: NPWP | G4: NAMA | H4: JENIS KELAMIN | I4: ALAMAT | J4: JABATAN | K4: STATUS | L4: KATEGORI TER | M4: GROSS UP | N4: GAJI | Q4: GAJI DILAPOR KE BPJS | R4: GAJI | S4: TUNJANGAN | W4: BPJS JKK,JKM | Y4: IURAN JHT | AA4: IURAN JP TK | AC4: IURAN BPJS KES | AE4: JUMLAH TUNJANGAN BPJS DITANGGUNG PESERTA | AF4: JUMLAH TUNJANGAN BPJS DITANGGUNG PERUSAHAAN | AG4: PENGHASILAN BRUTO | AH4: PENGHASILAN TIDAK TERATUR | AK4: TOTAL PENGHASILAN TIDAK TERATUR | AL4: TOTAL P. BRUTO | AN4: GAJI | AQ4: LAPOR BPJS | AR4: GAJI | AS4: TUNJANGAN | AW4: BPJS JKK,JKM | AY4: IURAN JHT | BA4: IURAN JP TK | BC4: IURAN BPJS KES | BE4: JUMLAH TUNJANGAN BPJS DITANGGUNG PESERTA | BF4: JUMLAH TUNJANGAN BPJS DITANGGUNG PERUSAHAAN | BG4: PENGHASILAN BRUTO | BH4: PENGHASILAN TIDAK TERATUR | BK4: TOTAL PENGHASILAN TIDAK TERATUR | BL4: TOTAL P. BRUTO | BN4: GAJI | BQ4: LAPOR BPJS | BR4: GAJI | BS4: TUNJANGAN | BW4: BPJS JKK,JKM | BY4: IURAN JHT | CA4: IURAN JP TK | CC4: IURAN BPJS KES | CE4: JUMLAH TUNJANGAN BPJS DITANGGUNG PESERTA | CF4: JUMLAH TUNJANGAN BPJS DITANGGUNG PERUSAHAAN | CG4: PENGHASILAN BRUTO | CH4: PENGHASILAN TIDAK TERATUR | CK4: TOTAL PENGHASILAN TIDAK TERATUR | CL4: TOTAL P. BRUTO | CN4: GAJI | CQ4: LAPOR BPJS | CR4: GAJI | CS4: TUNJANGAN | CW4: BPJS JKK,JKM | CY4: IURAN JHT | DA4: IURAN JP TK | DC4: IURAN BPJS KES | DE4: JUMLAH TUNJANGAN BPJS DITANGGUNG PESERTA | DF4: JUMLAH TUNJANGAN BPJS DITANGGUNG PERUSAHAAN | DG4: PENGHASILAN BRUTO | DH4: PENGHASILAN TIDAK TERATUR | DK4: TOTAL PENGHASILAN TIDAK TERATUR | DL4: TOTAL P. BRUTO | DN4: GAJI | DQ4: LAPOR BPJS | DR4: GAJI | DS4: TUNJANGAN | DW4: BPJS JKK,JKM | DY4: IURAN JHT | EA4: IURAN JP TK | EC4: IURAN BPJS KES | EE4: JUMLAH TUNJANGAN BPJS DITANGGUNG PESERTA | EF4: JUMLAH TUNJANGAN BPJS DITANGGUNG PERUSAHAAN | EG4: PENGHASILAN BRUTO | EH4: PENGHASILAN TIDAK TERATUR | EK4: TOTAL PENGHASILAN TIDAK TERATUR | EL4: TOTAL P. BRUTO | EN4: GAJI | EQ4: LAPOR BPJS | ER4: GAJI | ES4: TUNJANGAN | EW4: BPJS JKK,JKM | EY4: IURAN JHT | FA4: IURAN JP TK | FC4: IURAN BPJS KES | FE4: JUMLAH TUNJANGAN BPJS DITANGGUNG PESERTA | FF4: JUMLAH TUNJANGAN BPJS DITANGGUNG PERUSAHAAN | FG4: PENGHASILAN BRUTO | FH4: PENGHASILAN TIDAK TERATUR | FK4: TOTAL PENGHASILAN TIDAK TERATUR | FL4: TOTAL P. BRUTO | FN4: GAJI | FQ4: LAPOR BPJS | FR4: GAJI | FS4: TUNJANGAN | FW4: BPJS JKK,JKM | FY4: IURAN JHT | GA4: IURAN JP TK | GC4: IURAN BPJS KES | GE4: JUMLAH TUNJANGAN BPJS DITANGGUNG PESERTA | GF4: JUMLAH TUNJANGAN BPJS DITANGGUNG PERUSAHAAN | GG4: PENGHASILAN BRUTO | GH4: PENGHASILAN TIDAK TERATUR | GK4: TOTAL PENGHASILAN TIDAK TERATUR | GL4: TOTAL P. BRUTO | GN4: GAJI | GQ4: LAPOR BPJS | GR4: GAJI | GS4: TUNJANGAN | GW4: BPJS JKK,JKM | GY4: IURAN JHT | HA4: IURAN JP TK | HC4: IURAN BPJS KES | HE4: JUMLAH TUNJANGAN BPJS DITANGGUNG PESERTA | HF4: JUMLAH TUNJANGAN BPJS DITANGGUNG PERUSAHAAN | HG4: PENGHASILAN BRUTO | HH4: PENGHASILAN TIDAK TERATUR | HK4: TOTAL PENGHASILAN TIDAK TERATUR | HL4: TOTAL P. BRUTO | HN4: GAJI | HQ4: LAPOR BPJS | HR4: GAJI | HS4: TUNJANGAN | HW4: BPJS JKK,JKM | HY4: IURAN JHT | IA4: IURAN JP TK | IC4: IURAN BPJS KES | IE4: JUMLAH TUNJANGAN BPJS DITANGGUNG PESERTA | IF4: JUMLAH TUNJANGAN BPJS DITANGGUNG PERUSAHAAN | IG4: PENGHASILAN BRUTO | IH4: PENGHASILAN TIDAK TERATUR | IK4: TOTAL PENGHASILAN TIDAK TERATUR | IL4: TOTAL P. BRUTO | IN4: GAJI | IQ4: LAPOR BPJS | IR4: GAJI | IS4: TUNJANGAN | IW4: BPJS JKK,JKM | IY4: IURAN JHT | JA4: IURAN JP TK | JC4: IURAN BPJS KES | JE4: JUMLAH TUNJANGAN BPJS DITANGGUNG PESERTA | JF4: JUMLAH TUNJANGAN BPJS DITANGGUNG PERUSAHAAN | JG4: PENGHASILAN BRUTO | JH4: PENGHASILAN TIDAK TERATUR | JK4: TOTAL PENGHASILAN TIDAK TERATUR | JL4: TOTAL P. BRUTO | JN4: GAJI | JQ4: LAPOR BPJS | JR4: GAJI | JS4: TUNJANGAN | JW4: BPJS JKK,JKM | JY4: IURAN JHT | KA4: IURAN JP TK | KC4: IURAN BPJS KES | KE4: JUMLAH TUNJANGAN BPJS DITANGGUNG PESERTA | KF4: JUMLAH TUNJANGAN BPJS DITANGGUNG PERUSAHAAN | KG4: PENGHASILAN BRUTO | KH4: PENGHASILAN TIDAK TERATUR | KK4: TOTAL PENGHASILAN TIDAK TERATUR | KL4: TOTAL P. BRUTO | KN4: GAJI | KQ4: LAPOR BPJS | KR4: GAJI | KS4: TUNJANGAN | KW4: BPJS JKK,JKM | KY4: IURAN JHT | LA4: IURAN JP TK | LC4: IURAN BPJS KES | LE4: JUMLAH TUNJANGAN BPJS DITANGGUNG PESERTA | LF4: JUMLAH TUNJANGAN BPJS DITANGGUNG PERUSAHAAN | LG4: PENGHASILAN BRUTO | LH4: PENGHASILAN TIDAK TERATUR | LK4: TOTAL PENGHASILAN TIDAK TERATUR | LL4: TOTAL P. BRUTO
N5: GAJI POKOK | O5: TJ. JABATAN | P5: JUMLAH | S5: TJ. KERJA | T5: HP/KOMUNIKASI | U5: TRANSPORT/KENDARAAN | V5: TJ. LAINYA | W5: BPJS JKK 0,24% | X5: BPJS JKM 0,30% | Y5: IURAN JHT TENAGA KERJA 3% | Z5: IURAN JHT PEMBERI KERJA 2% | AA5: TENAGA KERJA 1% | AB5: PEMBERI KERJA 2% | AC5: TENAGA KERJA (1%) | AD5: PEMBERI KERJA (4%) | AH5: TJ. HARIAN | AI5: INSENTIF/BONUS | AJ5: THR | AN5: GAJI POKOK | AO5: TJ. JABATAN | AP5: JUMLAH | AS5: TJ. KERJA | AT5: HP/KOMUNIKASI | AU5: TRANSPORT/KENDARAAN | AV5: TJ. LAINYA | AW5: BPJS JKK 0,24% | AX5: BPJS JKM 0,30% | AY5: IURAN JHT TENAGA KERJA 3% | AZ5: IURAN JHT PEMBERI KERJA 2% | BA5: TENAGA KERJA 1% | BB5: PEMBERI KERJA 2% | BC5: TENAGA KERJA (1%) | BD5: PEMBERI KERJA (4%) | BH5: TJ. HARIAN | BI5: INSENTIF/BONUS | BJ5: THR | BN5: GAJI POKOK | BO5: TJ. JABATAN | BP5: JUMLAH | BS5: TJ. KERJA | BT5: HP/KOMUNIKASI | BU5: TRANSPORT/KENDARAAN | BV5: TJ. LAINYA | BW5: BPJS JKK 0,24% | BX5: BPJS JKM 0,30% | BY5: IURAN JHT TENAGA KERJA 3% | BZ5: IURAN JHT PEMBERI KERJA 2% | CA5: TENAGA KERJA 1% | CB5: PEMBERI KERJA 2% | CC5: TENAGA KERJA (1%) | CD5: PEMBERI KERJA (4%) | CH5: TJ. HARIAN | CI5: INSENTIF/BONUS | CJ5: THR | CN5: GAJI POKOK | CO5: TJ. JABATAN | CP5: JUMLAH | CS5: TJ. KERJA | CT5: HP/KOMUNIKASI | CU5: TRANSPORT/KENDARAAN | CV5: TJ. LAINYA | CW5: BPJS JKK 0,24% | CX5: BPJS JKM 0,30% | CY5: IURAN JHT TENAGA KERJA 3% | CZ5: IURAN JHT PEMBERI KERJA 2% | DA5: TENAGA KERJA 1% | DB5: PEMBERI KERJA 2% | DC5: TENAGA KERJA (1%) | DD5: PEMBERI KERJA (4%) | DH5: TJ. HARIAN | DI5: INSENTIF/BONUS | DJ5: THR | DN5: GAJI POKOK | DO5: TJ. JABATAN | DP5: JUMLAH | DS5: TJ. KERJA | DT5: HP/KOMUNIKASI | DU5: TRANSPORT/KENDARAAN | DV5: TJ. LAINYA | DW5: BPJS JKK 0,24% | DX5: BPJS JKM 0,30% | DY5: IURAN JHT TENAGA KERJA 3% | DZ5: IURAN JHT PEMBERI KERJA 2% | EA5: TENAGA KERJA 1% | EB5: PEMBERI KERJA 2% | EC5: TENAGA KERJA (1%) | ED5: PEMBERI KERJA (4%) | EH5: TJ. HARIAN | EI5: INSENTIF/BONUS | EJ5: THR | EN5: GAJI POKOK | EO5: TJ. JABATAN | EP5: JUMLAH | ES5: TJ. KERJA | ET5: HP/KOMUNIKASI | EU5: TRANSPORT/KENDARAAN | EV5: TJ. LAINYA | EW5: BPJS JKK 0,24% | EX5: BPJS JKM 0,30% | EY5: IURAN JHT TENAGA KERJA 3% | EZ5: IURAN JHT PEMBERI KERJA 2% | FA5: TENAGA KERJA 1% | FB5: PEMBERI KERJA 2% | FC5: TENAGA KERJA (1%) | FD5: PEMBERI KERJA (4%) | FH5: TJ. HARIAN | FI5: INSENTIF/BONUS | FJ5: THR | FN5: GAJI POKOK | FO5: TJ. JABATAN | FP5: JUMLAH | FS5: TJ. KERJA | FT5: HP/KOMUNIKASI | FU5: TRANSPORT/KENDARAAN | FV5: TJ. LAINYA | FW5: BPJS JKK 0,24% | FX5: BPJS JKM 0,30% | FY5: IURAN JHT TENAGA KERJA 3% | FZ5: IURAN JHT PEMBERI KERJA 2% | GA5: TENAGA KERJA 1% | GB5: PEMBERI KERJA 2% | GC5: TENAGA KERJA (1%) | GD5: PEMBERI KERJA (4%) | GH5: TJ. HARIAN | GI5: INSENTIF/BONUS | GJ5: THR | GN5: GAJI POKOK | GO5: TJ. JABATAN | GP5: JUMLAH | GS5: TJ. KERJA | GT5: HP/KOMUNIKASI | GU5: TRANSPORT/KENDARAAN | GV5: TJ. LAINYA | GW5: BPJS JKK 0,24% | GX5: BPJS JKM 0,30% | GY5: IURAN JHT TENAGA KERJA 3% | GZ5: IURAN JHT PEMBERI KERJA 2% | HA5: TENAGA KERJA 1% | HB5: PEMBERI KERJA 2% | HC5: TENAGA KERJA (1%) | HD5: PEMBERI KERJA (4%) | HH5: TJ. HARIAN | HI5: INSENTIF/BONUS | HJ5: THR | HN5: GAJI POKOK | HO5: TJ. JABATAN | HP5: JUMLAH | HS5: TJ. KERJA | HT5: HP/KOMUNIKASI | HU5: TRANSPORT/KENDARAAN | HV5: TJ. LAINYA | HW5: BPJS JKK 0,24% | HX5: BPJS JKM 0,30% | HY5: IURAN JHT TENAGA KERJA 3% | HZ5: IURAN JHT PEMBERI KERJA 2% | IA5: TENAGA KERJA 1% | IB5: PEMBERI KERJA 2% | IC5: TENAGA KERJA (1%) | ID5: PEMBERI KERJA (4%) | IH5: TJ. HARIAN | II5: INSENTIF/BONUS | IJ5: THR | IN5: GAJI POKOK | IO5: TJ. JABATAN | IP5: JUMLAH | IS5: TJ. KERJA | IT5: HP/KOMUNIKASI | IU5: TRANSPORT/KENDARAAN | IV5: TJ. LAINYA | IW5: BPJS JKK 0,24% | IX5: BPJS JKM 0,30% | IY5: IURAN JHT TENAGA KERJA 3% | IZ5: IURAN JHT PEMBERI KERJA 2% | JA5: TENAGA KERJA 1% | JB5: PEMBERI KERJA 2% | JC5: TENAGA KERJA (1%) | JD5: PEMBERI KERJA (4%) | JH5: TJ. HARIAN | JI5: INSENTIF/BONUS | JJ5: THR | JN5: GAJI POKOK | JO5: TJ. JABATAN | JP5: JUMLAH | JS5: TJ. KERJA | JT5: HP/KOMUNIKASI | JU5: TRANSPORT/KENDARAAN | JV5: TJ. LAINYA | JW5: BPJS JKK 0,24% | JX5: BPJS JKM 0,30% | JY5: IURAN JHT TENAGA KERJA 3% | JZ5: IURAN JHT PEMBERI KERJA 2% | KA5: TENAGA KERJA 1% | KB5: PEMBERI KERJA 2% | KC5: TENAGA KERJA (1%) | KD5: PEMBERI KERJA (4%) | KH5: TJ. HARIAN | KI5: INSENTIF/BONUS | KJ5: THR | KN5: GAJI POKOK | KO5: TJ. JABATAN | KP5: JUMLAH | KS5: TJ. KERJA | KT5: HP/KOMUNIKASI | KU5: TRANSPORT/KENDARAAN | KV5: TJ. LAINYA | KW5: BPJS JKK 0,24% | KX5: BPJS JKM 0,30% | KY5: IURAN JHT TENAGA KERJA 3% | KZ5: IURAN JHT PEMBERI KERJA 2% | LA5: TENAGA KERJA 1% | LB5: PEMBERI KERJA 2% | LC5: TENAGA KERJA (1%) | LD5: PEMBERI KERJA (4%) | LH5: TJ. HARIAN | LI5: INSENTIF/BONUS | LJ5: THR | LO5: REKAP TJ HARIAN SETAHU
A6: PEGAWAI TETAP
P46: =SUM(P7:P45) -> 0 | Q46: =SUM(Q7:Q45) -> 0 | R46: =SUM(R7:R45) -> 0 | S46: =SUM(S7:S45) -> 0 | T46: =SUM(T7:T45) -> 0 | U46: =SUM(U7:U45) -> 0 | V46: =SUM(V7:V45) -> 0 | W46: =SUM(W7:W45) -> 0 | ... AJ46: =SUM(AJ7:AJ45) -> 0 | AK46: =SUM(AK7:APD45) -> 0 | AL46: =SUM(AL7:AL45) -> 0 | AP46: =SUM(AP7:AP45) -> 0 | AQ46: =SUM(AQ7:AQ45) -> 0 | AR46: =SUM(AR7:AR45) -> 0 | AS46: =SUM(AS7:AS45) -> 0 | AT46: =SUM(AT7:AT45) -> 0 | AU46: =SUM(AU7:AU45) -> 0 | AV46: =SUM(AV7:AV45) -> 0 | AW46: =SUM(AW7:AW45) -> 0 | ... BJ46: =SUM(BJ7:BJ45) -> 0 | BK46: =SUM(BK7:AQD45) -> 0 | BL46: =SUM(BL7:BL45) -> 0 | BP46: =SUM(BP7:BP45) -> 0 | BQ46: =SUM(BQ7:BQ45) -> 0 | BR46: =SUM(BR7:BR45) -> 0 | BS46: =SUM(BS7:BS45) -> 0 | BT46: =SUM(BT7:BT45) -> 0 | BU46: =SUM(BU7:BU45) -> 0 | BV46: =SUM(BV7:BV45) -> 0 | BW46: =SUM(BW7:BW45) -> 0 | ... CJ46: =SUM(CJ7:CJ45) -> 0 | CK46: =SUM(CK7:ARD45) -> 0 | CL46: =SUM(CL7:CL45) -> 0 | CP46: =SUM(CP7:CP45) -> 0 | CQ46: =SUM(CQ7:CQ45) -> 0 | CR46: =SUM(CR7:CR45) -> 0 | CS46: =SUM(CS7:CS45) -> 0 | CT46: =SUM(CT7:CT45) -> 0 | CU46: =SUM(CU7:CU45) -> 0 | CV46: =SUM(CV7:CV45) -> 0 | CW46: =SUM(CW7:CW45) -> 0 | ... DJ46: =SUM(DJ7:DJ45) -> 0 | DK46: =SUM(DK7:ASD45) -> 0 | DL46: =SUM(DL7:DL45) -> 0 | DP46: =SUM(DP7:DP45) -> 0 | DQ46: =SUM(DQ7:DQ45) -> 0 | DR46: =SUM(DR7:DR45) -> 0 | DS46: =SUM(DS7:DS45) -> 0 | DT46: =SUM(DT7:DT45) -> 0 | DU46: =SUM(DU7:DU45) -> 0 | DV46: =SUM(DV7:DV45) -> 0 | DW46: =SUM(DW7:DW45) -> 0 | ... EJ46: =SUM(EJ7:EJ45) -> 0 | EK46: =SUM(EK7:ATD45) -> 0 | EL46: =SUM(EL7:EL45) -> 0 | EP46: =SUM(EP7:EP45) -> 0 | EQ46: =SUM(EQ7:EQ45) -> 0 | ER46: =SUM(ER7:ER45) -> 0 | ES46: =SUM(ES7:ES45) -> 0 | ET46: =SUM(ET7:ET45) -> 0 | EU46: =SUM(EU7:EU45) -> 0 | EV46: =SUM(EV7:EV45) -> 0 | EW46: =SUM(EW7:EW45) -> 0 | ... FJ46: =SUM(FJ7:FJ45) -> 0 | FK46: =SUM(FK7:AUD45) -> 0 | FL46: =SUM(FL7:FL45) -> 0 | FP46: =SUM(FP7:FP45) -> 0 | FQ46: =SUM(FQ7:FQ45) -> 0 | FR46: =SUM(FR7:FR45) -> 0 | FS46: =SUM(FS7:FS45) -> 0 | FT46: =SUM(FT7:FT45) -> 0 | FU46: =SUM(FU7:FU45) -> 0 | FV46: =SUM(FV7:FV45) -> 0 | FW46: =SUM(FW7:FW45) -> 0 | ... GJ46: =SUM(GJ7:GJ45) -> 0 | GK46: =SUM(GK7:AVD45) -> 0 | GL46: =SUM(GL7:GL45) -> 0 | GP46: =SUM(GP7:GP45) -> 0 | GQ46: =SUM(GQ7:GQ45) -> 0 | GR46: =SUM(GR7:GR45) -> 0 | GS46: =SUM(GS7:GS45) -> 0 | GT46: =SUM(GT7:GT45) -> 0 | GU46: =SUM(GU7:GU45) -> 0 | GV46: =SUM(GV7:GV45) -> 0 | GW46: =SUM(GW7:GW45) -> 0 | ... HJ46: =SUM(HJ7:HJ45) -> 0 | HK46: =SUM(HK7:AWD45) -> 0 | HL46: =SUM(HL7:HL45) -> 0 | HP46: =SUM(HP7:HP45) -> 0 | HQ46: =SUM(HQ7:HQ45) -> 0 | HR46: =SUM(HR7:HR45) -> 0 | HS46: =SUM(HS7:HS45) -> 0 | HT46: =SUM(HT7:HT45) -> 0 | HU46: =SUM(HU7:HU45) -> 0 | HV46: =SUM(HV7:HV45) -> 0 | HW46: =SUM(HW7:HW45) -> 0 | ... IJ46: =SUM(IJ7:IJ45) -> 0 | IK46: =SUM(IK7:AXD45) -> 0 | IL46: =SUM(IL7:IL45) -> 0 | IP46: =SUM(IP7:IP45) -> 0 | IQ46: =SUM(IQ7:IQ45) -> 0 | IR46: =SUM(IR7:IR45) -> 0 | IS46: =SUM(IS7:IS45) -> 0 | IT46: =SUM(IT7:IT45) -> 0 | IU46: =SUM(IU7:IU45) -> 0 | IV46: =SUM(IV7:IV45) -> 0 | IW46: =SUM(IW7:IW45) -> 0 | ... JJ46: =SUM(JJ7:JJ45) -> 0 | JK46: =SUM(JK7:AYD45) -> 0 | JL46: =SUM(JL7:JL45) -> 0 | JP46: =SUM(JP7:JP45) -> 0 | JQ46: =SUM(JQ7:JQ45) -> 0 | JR46: =SUM(JR7:JR45) -> 0 | JS46: =SUM(JS7:JS45) -> 0 | JT46: =SUM(JT7:JT45) -> 0 | JU46: =SUM(JU7:JU45) -> 0 | JV46: =SUM(JV7:JV45) -> 0 | JW46: =SUM(JW7:JW45) -> 0 | ... KJ46: =SUM(KJ7:KJ45) -> 0 | KK46: =SUM(KK7:AZD45) -> 0 | KL46: =SUM(KL7:KL45) -> 0 | KP46: =SUM(KP7:KP45) -> 0 | KQ46: =SUM(KQ7:KQ45) -> 0 | KR46: =SUM(KR7:KR45) -> 0 | KS46: =SUM(KS7:KS45) -> 0 | KT46: =SUM(KT7:KT45) -> 0 | KU46: =SUM(KU7:KU45) -> 0 | KV46: =SUM(KV7:KV45) -> 0 | KW46: =SUM(KW7:KW45) -> 0 | ... LJ46: =SUM(LJ7:LJ45) -> 0 | LK46: =SUM(LK7:BAD45) -> 0 | LL46: =SUM(LL7:LL45) -> 0 | LO46: =SUM(LO7:LO45) -> 0
AE48: PEMBAYARAN BPJS BULANAN | AF48: =AE46+AF46 -> 0 | BE48: PEMBAYARAN BPJS BULANAN | BF48: =BE46+BF46 -> 0 | CE48: PEMBAYARAN BPJS BULANAN | CF48: =CE46+CF46 -> 0 | DE48: PEMBAYARAN BPJS BULANAN | DF48: =DE46+DF46 -> 0 | EE48: PEMBAYARAN BPJS BULANAN | EF48: =EE46+EF46 -> 0 | FE48: PEMBAYARAN BPJS BULANAN | FF48: =FE46+FF46 -> 0 | GE48: PEMBAYARAN BPJS BULANAN | GF48: =GE46+GF46 -> 0 | HE48: PEMBAYARAN BPJS BULANAN | HF48: =HE46+HF46 -> 0 | IE48: PEMBAYARAN BPJS BULANAN | IF48: =IE46+IF46 -> 0 | JE48: PEMBAYARAN BPJS BULANAN | JF48: =JE46+JF46 -> 0 | KE48: PEMBAYARAN BPJS BULANAN | KF48: =KE46+KF46 -> 0 | LE48: PEMBAYARAN BPJS BULANAN | LF48: =LE46+LF46 -> 0

Sheet Jan-Nov
A1: PT. X
A2: PERHITUNGAN PPh 21 BULANAN (TER PP 58 Tahun 2023)
A3: BULAN JANUARI 2024
A4: NO. | B4: NIP | C4: NIK (KTP) | D4: BULAN MASUK KERJA | E4: NPWP | G4: NAMA | H4: JENIS KELAMIN | I4: ALAMAT | J4: JABATAN | K4: STATUS | L4: KATEGORI TER | M4: HARI KERJA | N4: TOTAL HADIR | O4: GROSS UP | P4: PENGHASILAN BRUTO JANUARI | W4: PENGHASILAN BRUTO FEBRUARI | AD4: PENGHASILAN BRUTO MARET | AK4: PENGHASILAN BRUTO APRIL | AR4: PENGHASILAN BRUTO MEI | AY4: PENGHASILAN BRUTO JUNI | BF4: PENGHASILAN BRUTO JULI | BM4: PENGHASILAN BRUTO AGUSTUS | BT4: PENGHASILAN BRUTO SEPTEMBER | CA4: PENGHASILAN BRUTO OKTOBER | CH4: PENGHASILAN BRUTO NOVEMBER | CO4: PENGHASILAN BRUTO DESEMBER
P5: P. BRUTO | Q5: TARIF TER | R5: GROSS UP | S5: BRUTO | T5: TARIF TER | U5: PPh 21 PERBULAN | W5: P. BRUTO | X5: TARIF TER | Y5: GROSS UP | Z5: BRUTO | AA5: TARIF TER | AB5: PPh 21 PERBULAN | AD5: P. BRUTO | AE5: TARIF TER | AF5: GROSS UP | AG5: BRUTO | AH5: TARIF TER | AI5: PPh 21 PERBULAN | AK5: P. BRUTO | AL5: TARIF TER | AM5: GROSS UP | AN5: BRUTO | AO5: TARIF TER | AP5: PPh 21 PERBULAN | AR5: P. BRUTO | AS5: TARIF TER | AT5: GROSS UP | AU5: BRUTO | AV5: TARIF TER | AW5: PPh 21 PERBULAN | AY5: P. BRUTO | AZ5: TARIF TER | BA5: GROSS UP | BB5: BRUTO | BC5: TARIF TER | BD5: PPh 21 PERBULAN | BF5: P. BRUTO | BG5: TARIF TER | BH5: GROSS UP | BI5: BRUTO | BJ5: TARIF TER | BK5: PPh 21 PERBULAN | BM5: P. BRUTO | BN5: TARIF TER | BO5: GROSS UP | BP5: BRUTO | BQ5: TARIF TER | BR5: PPh 21 PERBULAN | BT5: P. BRUTO | BU5: TARIF TER | BV5: GROSS UP | BW5: BRUTO | BX5: TARIF TER | BY5: PPh 21 PERBULAN | CA5: P. BRUTO | CB5: TARIF TER | CC5: GROSS UP | CD5: BRUTO | CE5: TARIF TER | CF5: PPh 21 PERBULAN | CH5: P. BRUTO | CI5: TARIF TER | CJ5: GROSS UP | CK5: BRUTO | CL5: TARIF TER | CM5: PPh 21 PERBULAN | CO5: P. BRUTO | CP5: TARIF TER | CQ5: GROSS UP | CR5: BRUTO | CS5: TARIF TER | CT5: PPh 21 PERBULAN
A6: PEGAWAI TETAP
A7: 1 | K7: ='Data Gaji'!K7 -> 0 | L7: =IF(ISNA(VLOOKUP(K7,'PTKP & TARIF'!$D$4:$E$11,2,0)),"",VLOOKUP(K7,'PTKP & TARIF'!$D$4:$E$11,2,0)) | M7: 26 | N7: 26 | O7: TIDAK | P7: ='Data Gaji'!AL7 -> 0 | Q7: =IF($L7="TER A",VLOOKUP(P7,TER!$A$5:$D$48,4,TRUE),IF($L7="TER B",VLOOKUP(P7,TER!$F$5:$I$44,4,TRUE),IF($L7="TER C",VLOOKUP(P7,TER!$K$5:$N$45,4,TRUE),0))) -> 0 | R7: =IF($O7="Ya",P7*Q7,0) -> 0 | S7: =P7+R7 -> 0 | T7: =IF($L7="TER A",VLOOKUP(P7,TER!$A$5:$D$48,4,TRUE),IF($L7="TER B",VLOOKUP(P7,TER!$F$5:$I$44,4,TRUE),IF($L7="TER C",VLOOKUP(P7,TER!$K$5:$N$45,4,TRUE),0))) -> 0 | U7: =ROUND(S7*T7,2) -> 0 | W7: ='Data Gaji'!BL7 -> 0 | X7: =IF($L7="TER A",VLOOKUP(W7,TER!$A$5:$D$48,4,TRUE),IF($L7="TER B",VLOOKUP(W7,TER!$F$5:$I$44,4,TRUE),IF($L7="TER C",VLOOKUP(W7,TER!$K$5:$N$45,4,TRUE),0))) -> 0 | Y7: =IF($O7="Ya",W7*X7,0) -> 0 | Z7: =W7+Y7 -> 0 | AA7: =IF($L7="TER A",VLOOKUP(W7,TER!$A$5:$D$48,4,TRUE),IF($L7="TER B",VLOOKUP(W7,TER!$F$5:$I$44,4,TRUE),IF($L7="TER C",VLOOKUP(W7,TER!$K$5:$N$45,4,TRUE),0))) -> 0 | AB7: =ROUND(Z7*AA7,0) -> 0 | AD7: ='Data Gaji'!CL7 -> 0 | AE7: =IF($L7="TER A",VLOOKUP(AD7,TER!$A$5:$D$48,4,TRUE),IF($L7="TER B",VLOOKUP(AD7,TER!$F$5:$I$44,4,TRUE),IF($L7="TER C",VLOOKUP(AD7,TER!$K$5:$N$45,4,TRUE),0))) -> 0 | AF7: =IF($O7="Ya",AD7*AE7,0) -> 0 | AG7: =AD7+AF7 -> 0 | AH7: =IF($L7="TER A",VLOOKUP(AD7,TER!$A$5:$D$48,4,TRUE),IF($L7="TER B",VLOOKUP(AD7,TER!$F$5:$I$44,4,TRUE),IF($L7="TER C",VLOOKUP(AD7,TER!$K$5:$N$45,4,TRUE),0))) -> 0 | AI7: =ROUND(AG7*AH7,0) -> 0 | AK7: ='Data Gaji'!DL7 -> 0 | AL7: =IF($L7="TER A",VLOOKUP(AK7,TER!$A$5:$D$48,4,TRUE),IF($L7="TER B",VLOOKUP(AK7,TER!$F$5:$I$44,4,TRUE),IF($L7="TER C",VLOOKUP(AK7,TER!$K$5:$N$45,4,TRUE),0))) -> 0 | AM7: =IF($O7="Ya",AK7*AL7,0) -> 0 | AN7: =AK7+AM7 -> 0 | AO7: =IF($L7="TER A",VLOOKUP(AK7,TER!$A$5:$D$48,4,TRUE),IF($L7="TER B",VLOOKUP(AK7,TER!$F$5:$I$44,4,TRUE),IF($L7="TER C",VLOOKUP(AK7,TER!$K$5:$N$45,4,TRUE),0))) -> 0 | AP7: =ROUND(AN7*AO7,0) -> 0 | AR7: ='Data Gaji'!EL7 -> 0 | AS7: =IF($L7="TER A",VLOOKUP(AR7,TER!$A$5:$D$48,4,TRUE),IF($L7="TER B",VLOOKUP(AR7,TER!$F$5:$I$44,4,TRUE),IF($L7="TER C",VLOOKUP(AR7,TER!$K$5:$N$45,4,TRUE),0))) -> 0 | AT7: =IF($O7="Ya",AR7*AS7,0) -> 0 | AU7: =AR7+AT7 -> 0 | AV7: =IF($L7="TER A",VLOOKUP(AR7,TER!$A$5:$D$48,4,TRUE),IF($L7="TER B",VLOOKUP(AR7,TER!$F$5:$I$44,4,TRUE),IF($L7="TER C",VLOOKUP(AR7,TER!$K$5:$N$45,4,TRUE),0))) -> 0 | AW7: =ROUND(AU7*AV7,0) -> 0 | AY7: ='Data Gaji'!FL7 -> 0 | AZ7: =IF($L7="TER A",VLOOKUP(AY7,TER!$A$5:$D$48,4,TRUE),IF($L7="TER B",VLOOKUP(AY7,TER!$F$5:$I$44,4,TRUE),IF($L7="TER C",VLOOKUP(AY7,TER!$K$5:$N$45,4,TRUE),0))) -> 0 | BA7: =IF($O7="Ya",AY7*AZ7,0) -> 0 | BB7: =AY7+BA7 -> 0 | BC7: =IF($L7="TER A",VLOOKUP(AY7,TER!$A$5:$D$48,4,TRUE),IF($L7="TER B",VLOOKUP(AY7,TER!$F$5:$I$44,4,TRUE),IF($L7="TER C",VLOOKUP(AY7,TER!$K$5:$N$45,4,TRUE),0))) -> 0 | BD7: =ROUND(BB7*BC7,0) -> 0 | BF7: ='Data Gaji'!GL7 -> 0 | BG7: =IF($L7="TER A",VLOOKUP(BF7,TER!$A$5:$D$48,4,TRUE),IF($L7="TER B",VLOOKUP(BF7,TER!$F$5:$I$44,4,TRUE),IF($L7="TER C",VLOOKUP(BF7,TER!$K$5:$N$45,4,TRUE),0))) -> 0 | BH7: =IF($O7="Ya",BF7*BG7,0) -> 0 | BI7: =BF7+BH7 -> 0 | BJ7: =IF($L7="TER A",VLOOKUP(BF7,TER!$A$5:$D$48,4,TRUE),IF($L7="TER B",VLOOKUP(BF7,TER!$F$5:$I$44,4,TRUE),IF($L7="TER C",VLOOKUP(BF7,TER!$K$5:$N$45,4,TRUE),0))) -> 0 | BK7: =ROUND(BI7*BJ7,0) -> 0 | BM7: ='Data Gaji'!HL7 -> 0 | BN7: =IF($L7="TER A",VLOOKUP(BM7,TER!$A$5:$D$48,4,TRUE),IF($L7="TER B",VLOOKUP(BM7,TER!$F$5:$I$44,4,TRUE),IF($L7="TER C",VLOOKUP(BM7,TER!$K$5:$N$45,4,TRUE),0))) -> 0 | BO7: =IF($O7="Ya",BM7*BN7,0) -> 0 | BP7: =BM7+BO7 -> 0 | BQ7: =IF($L7="TER A",VLOOKUP(BM7,TER!$A$5:$D$48,4,TRUE),IF($L7="TER B",VLOOKUP(BM7,TER!$F$5:$I$44,4,TRUE),IF($L7="TER C",VLOOKUP(BM7,TER!$K$5:$N$45,4,TRUE),0))) -> 0 | BR7: =ROUND(BP7*BQ7,0) -> 0 | BT7: ='Data Gaji'!IL7 -> 0 | BU7: =IF($L7="TER A",VLOOKUP(BT7,TER!$A$5:$D$48,4,TRUE),IF($L7="TER B",VLOOKUP(BT7,TER!$F$5:$I$44,4,TRUE),IF($L7="TER C",VLOOKUP(BT7,TER!$K$5:$N$45,4,TRUE),0))) -> 0 | BV7: =IF($O7="Ya",BT7*BU7,0) -> 0 | BW7: =BT7+BV7 -> 0 | BX7: =IF($L7="TER A",VLOOKUP(BT7,TER!$A$5:$D$48,4,TRUE),IF($L7="TER B",VLOOKUP(BT7,TER!$F$5:$I$44,4,TRUE),IF($L7="TER C",VLOOKUP(BT7,TER!$K$5:$N$45,4,TRUE),0))) -> 0 | BY7: =ROUND(BW7*BX7,0) -> 0 | CA7: ='Data Gaji'!JL7 -> 0 | CB7: =IF($L7="TER A",VLOOKUP(CA7,TER!$A$5:$D$48,4,TRUE),IF($L7="TER B",VLOOKUP(CA7,TER!$F$5:$I$44,4,TRUE),IF($L7="TER C",VLOOKUP(CA7,TER!$K$5:$N$45,4,TRUE),0))) -> 0 | CC7: =IF($O7="Ya",CA7*CB7,0) -> 0 | CD7: =CA7+CC7 -> 0 | CE7: =IF($L7="TER A",VLOOKUP(CA7,TER!$A$5:$D$48,4,TRUE),IF($L7="TER B",VLOOKUP(CA7,TER!$F$5:$I$44,4,TRUE),IF($L7="TER C",VLOOKUP(CA7,TER!$K$5:$N$45,4,TRUE),0))) -> 0 | CF7: =ROUND(CD7*CE7,0) -> 0 | CH7: ='Data Gaji'!KL7 -> 0 | CI7: =IF($L7="TER A",VLOOKUP(CH7,TER!$A$5:$D$48,4,TRUE),IF($L7="TER B",VLOOKUP(CH7,TER!$F$5:$I$44,4,TRUE),IF($L7="TER C",VLOOKUP(CH7,TER!$K$5:$N$45,4,TRUE),0))) -> 0 | CJ7: =IF($O7="Ya",CH7*CI7,0) -> 0 | CK7: =CH7+CJ7 -> 0 | CL7: =IF($L7="TER A",VLOOKUP(CH7,TER!$A$5:$D$48,4,TRUE),IF($L7="TER B",VLOOKUP(CH7,TER!$F$5:$I$44,4,TRUE),IF($L7="TER C",VLOOKUP(CH7,TER!$K$5:$N$45,4,TRUE),0))) -> 0 | CM7: =ROUND(CK7*CL7,0) -> 0 | CO7: ='Data Gaji'!LL7 -> 0 | CP7: =IF($L7="TER A",VLOOKUP(CO7,TER!$A$5:$D$48,4,TRUE),IF($L7="TER B",VLOOKUP(CO7,TER!$F$5:$I$44,4,TRUE),IF($L7="TER C",VLOOKUP(CO7,TER!$K$5:$N$45,4,TRUE),0))) -> 0 | CQ7: =IF($O7="Ya",CO7*CP7,0) -> 0 | CR7: =CO7+CQ7 -> 0 | CS7: =IF($L7="TER A",VLOOKUP(CO7,TER!$A$5:$D$48,4,TRUE),IF($L7="TER B",VLOOKUP(CO7,TER!$F$5:$I$44,4,TRUE),IF($L7="TER C",VLOOKUP(CO7,TER!$K$5:$N$45,4,TRUE),0))) -> 0 | CT7: =CR7*CS7 -> 0
A8: =A7+1 -> 2 | K8: ='Data Gaji'!K8 -> 0 | L8: =IF(ISNA(VLOOKUP(K8,'PTKP & TARIF'!$D$4:$E$11,2,0)),"",VLOOKUP(K8,'PTKP & TARIF'!$D$4:$E$11,2,0)) | M8: 26 | N8: 26 | O8: TIDAK | P8: ='Data Gaji'!AL8 -> 0 | Q8: =IF($L8="TER A",VLOOKUP(P8,TER!$A$5:$D$48,4,TRUE),IF($L8="TER B",VLOOKUP(P8,TER!$F$5:$I$44,4,TRUE),IF($L8="TER C",VLOOKUP(P8,TER!$K$5:$N$45,4,TRUE),0))) -> 0 | R8: =IF($O8="Ya",P8*Q8,0) -> 0 | S8: =P8+R8 -> 0 | T8: =IF($L8="TER A",VLOOKUP(P8,TER!$A$5:$D$48,4,TRUE),IF($L8="TER B",VLOOKUP(P8,TER!$F$5:$I$44,4,TRUE),IF($L8="TER C",VLOOKUP(P8,TER!$K$5:$N$45,4,TRUE),0))) -> 0 | U8: =ROUND(S8*T8,0) -> 0 | W8: ='Data Gaji'!BL8 -> 0 | X8: =IF($L8="TER A",VLOOKUP(W8,TER!$A$5:$D$48,4,TRUE),IF($L8="TER B",VLOOKUP(W8,TER!$F$5:$I$44,4,TRUE),IF($L8="TER C",VLOOKUP(W8,TER!$K$5:$N$45,4,TRUE),0))) -> 0 | Y8: =IF($O8="Ya",W8*X8,0) -> 0 | Z8: =W8+Y8 -> 0 | AA8: =IF($L8="TER A",VLOOKUP(W8,TER!$A$5:$D$48,4,TRUE),IF($L8="TER B",VLOOKUP(W8,TER!$F$5:$I$44,4,TRUE),IF($L8="TER C",VLOOKUP(W8,TER!$K$5:$N$45,4,TRUE),0))) -> 0 | AB8: =ROUND(Z8*AA8,0) -> 0 | AD8: ='Data Gaji'!CL8 -> 0 | AE8: =IF($L8="TER A",VLOOKUP(AD8,TER!$A$5:$D$48,4,TRUE),IF($L8="TER B",VLOOKUP(AD8,TER!$F$5:$I$44,4,TRUE),IF($L8="TER C",VLOOKUP(AD8,TER!$K$5:$N$45,4,TRUE),0))) -> 0 | AF8: =IF($O8="Ya",AD8*AE8,0) -> 0 | AG8: =AD8+AF8 -> 0 | AH8: =IF($L8="TER A",VLOOKUP(AD8,TER!$A$5:$D$48,4,TRUE),IF($L8="TER B",VLOOKUP(AD8,TER!$F$5:$I$44,4,TRUE),IF($L8="TER C",VLOOKUP(AD8,TER!$K$5:$N$45,4,TRUE),0))) -> 0 | AI8: =ROUND(AG8*AH8,0) -> 0 | AK8: ='Data Gaji'!DL8 -> 0 | AL8: =IF($L8="TER A",VLOOKUP(AK8,TER!$A$5:$D$48,4,TRUE),IF($L8="TER B",VLOOKUP(AK8,TER!$F$5:$I$44,4,TRUE),IF($L8="TER C",VLOOKUP(AK8,TER!$K$5:$N$45,4,TRUE),0))) -> 0 | AM8: =IF($O8="Ya",AK8*AL8,0) -> 0 | AN8: =AK8+AM8 -> 0 | AO8: =IF($L8="TER A",VLOOKUP(AK8,TER!$A$5:$D$48,4,TRUE),IF($L8="TER B",VLOOKUP(AK8,TER!$F$5:$I$44,4,TRUE),IF($L8="TER C",VLOOKUP(AK8,TER!$K$5:$N$45,4,TRUE),0))) -> 0 | AP8: =ROUND(AN8*AO8,0) -> 0 | AR8: ='Data Gaji'!EL8 -> 0 | AS8: =IF($L8="TER A",VLOOKUP(AR8,TER!$A$5:$D$48,4,TRUE),IF($L8="TER B",VLOOKUP(AR8,TER!$F$5:$I$44,4,TRUE),IF($L8="TER C",VLOOKUP(AR8,TER!$K$5:$N$45,4,TRUE),0))) -> 0 | AT8: =IF($O8="Ya",AR8*AS8,0) -> 0 | AU8: =AR8+AT8 -> 0 | AV8: =IF($L8="TER A",VLOOKUP(AR8,TER!$A$5:$D$48,4,TRUE),IF($L8="TER B",VLOOKUP(AR8,TER!$F$5:$I$44,4,TRUE),IF($L8="TER C",VLOOKUP(AR8,TER!$K$5:$N$45,4,TRUE),0))) -> 0 | AW8: =ROUND(AU8*AV8,0) -> 0 | AY8: ='Data Gaji'!FL8 -> 0 | AZ8: =IF($L8="TER A",VLOOKUP(AY8,TER!$A$5:$D$48,4,TRUE),IF($L8="TER B",VLOOKUP(AY8,TER!$F$5:$I$44,4,TRUE),IF($L8="TER C",VLOOKUP(AY8,TER!$K$5:$N$45,4,TRUE),0))) -> 0 | BA8: =IF($O8="Ya",AY8*AZ8,0) -> 0 | BB8: =AY8+BA8 -> 0 | BC8: =IF($L8="TER A",VLOOKUP(AY8,TER!$A$5:$D$48,4,TRUE),IF($L8="TER B",VLOOKUP(AY8,TER!$F$5:$I$44,4,TRUE),IF($L8="TER C",VLOOKUP(AY8,TER!$K$5:$N$45,4,TRUE),0))) -> 0 | BD8: =ROUND(BB8*BC8,0) -> 0 | BF8: ='Data Gaji'!GL8 -> 0 | BG8: =IF($L8="TER A",VLOOKUP(BF8,TER!$A$5:$D$48,4,TRUE),IF($L8="TER B",VLOOKUP(BF8,TER!$F$5:$I$44,4,TRUE),IF($L8="TER C",VLOOKUP(BF8,TER!$K$5:$N$45,4,TRUE),0))) -> 0 | BH8: =IF($O8="Ya",BF8*BG8,0) -> 0 | BI8: =BF8+BH8 -> 0 | BJ8: =IF($L8="TER A",VLOOKUP(BF8,TER!$A$5:$D$48,4,TRUE),IF($L8="TER B",VLOOKUP(BF8,TER!$F$5:$I$44,4,TRUE),IF($L8="TER C",VLOOKUP(BF8,TER!$K$5:$N$45,4,TRUE),0))) -> 0 | BK8: =ROUND(BI8*BJ8,0) -> 0 | BM8: ='Data Gaji'!HL8 -> 0 | BN8: =IF($L8="TER A",VLOOKUP(BM8,TER!$A$5:$D$48,4,TRUE),IF($L8="TER B",VLOOKUP(BM8,TER!$F$5:$I$44,4,TRUE),IF($L8="TER C",VLOOKUP(BM8,TER!$K$5:$N$45,4,TRUE),0))) -> 0 | BO8: =IF($O8="Ya",BM8*BN8,0) -> 0 | BP8: =BM8+BO8 -> 0 | BQ8: =IF($L8="TER A",VLOOKUP(BM8,TER!$A$5:$D$48,4,TRUE),IF($L8="TER B",VLOOKUP(BM8,TER!$F$5:$I$44,4,TRUE),IF($L8="TER C",VLOOKUP(BM8,TER!$K$5:$N$45,4,TRUE),0))) -> 0 | BR8: =ROUND(BP8*BQ8,0) -> 0 | BT8: ='Data Gaji'!IL8 -> 0 | BU8: =IF($L8="TER A",VLOOKUP(BT8,TER!$A$5:$D$48,4,TRUE),IF($L8="TER B",VLOOKUP(BT8,TER!$F$5:$I$44,4,TRUE),IF($L8="TER C",VLOOKUP(BT8,TER!$K$5:$N$45,4,TRUE),0))) -> 0 | BV8: =IF($O8="Ya",BT8*BU8,0) -> 0 | BW8: =BT8+BV8 -> 0 | BX8: =IF($L8="TER A",VLOOKUP(BT8,TER!$A$5:$D$48,4,TRUE),IF($L8="TER B",VLOOKUP(BT8,TER!$F$5:$I$44,4,TRUE),IF($L8="TER C",VLOOKUP(BT8,TER!$K$5:$N$45,4,TRUE),0))) -> 0 | BY8: =ROUND(BW8*BX8,0) -> 0 | CA8: ='Data Gaji'!JL8 -> 0 | CB8: =IF($L8="TER A",VLOOKUP(CA8,TER!$A$5:$D$48,4,TRUE),IF($L8="TER B",VLOOKUP(CA8,TER!$F$5:$I$44,4,TRUE),IF($L8="TER C",VLOOKUP(CA8,TER!$K$5:$N$45,4,TRUE),0))) -> 0 | CC8: =IF($O8="Ya",CA8*CB8,0) -> 0 | CD8: =CA8+CC8 -> 0 | CE8: =IF($L8="TER A",VLOOKUP(CA8,TER!$A$5:$D$48,4,TRUE),IF($L8="TER B",VLOOKUP(CA8,TER!$F$5:$I$44,4,TRUE),IF($L8="TER C",VLOOKUP(CA8,TER!$K$5:$N$45,4,TRUE),0))) -> 0 | CF8: =ROUND(CD8*CE8,0) -> 0 | CH8: ='Data Gaji'!KL8 -> 0 | CI8: =IF($L8="TER A",VLOOKUP(CH8,TER!$A$5:$D$48,4,TRUE),IF($L8="TER B",VLOOKUP(CH8,TER!$F$5:$I$44,4,TRUE),IF($L8="TER C",VLOOKUP(CH8,TER!$K$5:$N$45,4,TRUE),0))) -> 0 | CJ8: =IF($O8="Ya",CH8*CI8,0) -> 0 | CK8: =CH8+CJ8 -> 0 | CL8: =IF($L8="TER A",VLOOKUP(CH8,TER!$A$5:$D$48,4,TRUE),IF($L8="TER B",VLOOKUP(CH8,TER!$F$5:$I$44,4,TRUE),IF($L8="TER C",VLOOKUP(CH8,TER!$K$5:$N$45,4,TRUE),0))) -> 0 | CM8: =ROUND(CK8*CL8,0) -> 0 | CO8: ='Data Gaji'!LL8 -> 0 | CP8: =IF($L8="TER A",VLOOKUP(CO8,TER!$A$5:$D$48,4,TRUE),IF($L8="TER B",VLOOKUP(CO8,TER!$F$5:$I$44,4,TRUE),IF($L8="TER C",VLOOKUP(CO8,TER!$K$5:$N$45,4,TRUE),0))) -> 0 | CQ8: =IF($O8="Ya",CO8*CP8,0) -> 0 | CR8: =CO8+CQ8 -> 0 | CS8: =IF($L8="TER A",VLOOKUP(CO8,TER!$A$5:$D$48,4,TRUE),IF($L8="TER B",VLOOKUP(CO8,TER!$F$5:$I$44,4,TRUE),IF($L8="TER C",VLOOKUP(CO8,TER!$K$5:$N$45,4,TRUE),0))) -> 0 | CT8: =CR8*CS8 -> 0
A9: =A8+1 -> 3 | K9: ='Data Gaji'!K9 -> 0 | L9: =IF(ISNA(VLOOKUP(K9,'PTKP & TARIF'!$D$4:$E$11,2,0)),"",VLOOKUP(K9,'PTKP & TARIF'!$D$4:$E$11,2,0)) | M9: 26 | N9: 26 | O9: TIDAK | P9: ='Data Gaji'!AL9 -> 0 | Q9: =IF($L9="TER A",VLOOKUP(P9,TER!$A$5:$D$48,4,TRUE),IF($L9="TER B",VLOOKUP(P9,TER!$F$5:$I$44,4,TRUE),IF($L9="TER C",VLOOKUP(P9,TER!$K$5:$N$45,4,TRUE),0))) -> 0 | R9: =IF($O9="Ya",P9*Q9,0) -> 0 | S9: =P9+R9 -> 0 | T9: =IF($L9="TER A",VLOOKUP(P9,TER!$A$5:$D$48,4,TRUE),IF($L9="TER B",VLOOKUP(P9,TER!$F$5:$I$44,4,TRUE),IF($L9="TER C",VLOOKUP(P9,TER!$K$5:$N$45,4,TRUE),0))) -> 0 | U9: =ROUND(S9*T9,2) -> 0 | W9: ='Data Gaji'!BL9 -> 0 | X9: =IF($L9="TER A",VLOOKUP(W9,TER!$A$5:$D$48,4,TRUE),IF($L9="TER B",VLOOKUP(W9,TER!$F$5:$I$44,4,TRUE),IF($L9="TER C",VLOOKUP(W9,TER!$K$5:$N$45,4,TRUE),0))) -> 0 | Y9: =IF($O9="Ya",W9*X9,0) -> 0 | Z9: =W9+Y9 -> 0 | AA9: =IF($L9="TER A",VLOOKUP(W9,TER!$A$5:$D$48,4,TRUE),IF($L9="TER B",VLOOKUP(W9,TER!$F$5:$I$44,4,TRUE),IF($L9="TER C",VLOOKUP(W9,TER!$K$5:$N$45,4,TRUE),0))) -> 0 | AB9: =ROUND(Z9*AA9,0) -> 0 | AD9: ='Data Gaji'!CL9 -> 0 | AE9: =IF($L9="TER A",VLOOKUP(AD9,TER!$A$5:$D$48,4,TRUE),IF($L9="TER B",VLOOKUP(AD9,TER!$F$5:$I$44,4,TRUE),IF($L9="TER C",VLOOKUP(AD9,TER!$K$5:$N$45,4,TRUE),0))) -> 0 | AF9: =IF($O9="Ya",AD9*AE9,0) -> 0 | AG9: =AD9+AF9 -> 0 | AH9: =IF($L9="TER A",VLOOKUP(AD9,TER!$A$5:$D$48,4,TRUE),IF($L9="TER B",VLOOKUP(AD9,TER!$F$5:$I$44,4,TRUE),IF($L9="TER C",VLOOKUP(AD9,TER!$K$5:$N$45,4,TRUE),0))) -> 0 | AI9: =ROUND(AG9*AH9,0) -> 0 | AK9: ='Data Gaji'!DL9 -> 0 | AL9: =IF($L9="TER A",VLOOKUP(AK9,TER!$A$5:$D$48,4,TRUE),IF($L9="TER B",VLOOKUP(AK9,TER!$F$5:$I$44,4,TRUE),IF($L9="TER C",VLOOKUP(AK9,TER!$K$5:$N$45,4,TRUE),0))) -> 0 | AM9: =IF($O9="Ya",AK9*AL9,0) -> 0 | AN9: =AK9+AM9 -> 0 | AO9: =IF($L9="TER A",VLOOKUP(AK9,TER!$A$5:$D$48,4,TRUE),IF($L9="TER B",VLOOKUP(AK9,TER!$F$5:$I$44,4,TRUE),IF($L9="TER C",VLOOKUP(AK9,TER!$K$5:$N$45,4,TRUE),0))) -> 0 | AP9: =ROUND(AN9*AO9,0) -> 0 | AR9: ='Data Gaji'!EL9 -> 0 | AS9: =IF($L9="TER A",VLOOKUP(AR9,TER!$A$5:$D$48,4,TRUE),IF($L9="TER B",VLOOKUP(AR9,TER!$F$5:$I$44,4,TRUE),IF($L9="TER C",VLOOKUP(AR9,TER!$K$5:$N$45,4,TRUE),0))) -> 0 | AT9: =IF($O9="Ya",AR9*AS9,0) -> 0 | AU9: =AR9+AT9 -> 0 | AV9: =IF($L9="TER A",VLOOKUP(AR9,TER!$A$5:$D$48,4,TRUE),IF($L9="TER B",VLOOKUP(AR9,TER!$F$5:$I$44,4,TRUE),IF($L9="TER C",VLOOKUP(AR9,TER!$K$5:$N$45,4,TRUE),0))) -> 0 | AW9: =ROUND(AU9*AV9,0) -> 0 | AY9: ='Data Gaji'!FL9 -> 0 | AZ9: =IF($L9="TER A",VLOOKUP(AY9,TER!$A$5:$D$48,4,TRUE),IF($L9="TER B",VLOOKUP(AY9,TER!$F$5:$I$44,4,TRUE),IF($L9="TER C",VLOOKUP(AY9,TER!$K$5:$N$45,4,TRUE),0))) -> 0 | BA9: =IF($O9="Ya",AY9*AZ9,0) -> 0 | BB9: =AY9+BA9 -> 0 | BC9: =IF($L9="TER A",VLOOKUP(AY9,TER!$A$5:$D$48,4,TRUE),IF($L9="TER B",VLOOKUP(AY9,TER!$F$5:$I$44,4,TRUE),IF($L9="TER C",VLOOKUP(AY9,TER!$K$5:$N$45,4,TRUE),0))) -> 0 | BD9: =ROUND(BB9*BC9,0) -> 0 | BF9: ='Data Gaji'!GL9 -> 0 | BG9: =IF($L9="TER A",VLOOKUP(BF9,TER!$A$5:$D$48,4,TRUE),IF($L9="TER B",VLOOKUP(BF9,TER!$F$5:$I$44,4,TRUE),IF($L9="TER C",VLOOKUP(BF9,TER!$K$5:$N$45,4,TRUE),0))) -> 0 | BH9: =IF($O9="Ya",BF9*BG9,0) -> 0 | BI9: =BF9+BH9 -> 0 | BJ9: =IF($L9="TER A",VLOOKUP(BF9,TER!$A$5:$D$48,4,TRUE),IF($L9="TER B",VLOOKUP(BF9,TER!$F$5:$I$44,4,TRUE),IF($L9="TER C",VLOOKUP(BF9,TER!$K$5:$N$45,4,TRUE),0))) -> 0 | BK9: =ROUND(BI9*BJ9,0) -> 0 | BM9: ='Data Gaji'!HL9 -> 0 | BN9: =IF($L9="TER A",VLOOKUP(BM9,TER!$A$5:$D$48,4,TRUE),IF($L9="TER B",VLOOKUP(BM9,TER!$F$5:$I$44,4,TRUE),IF($L9="TER C",VLOOKUP(BM9,TER!$K$5:$N$45,4,TRUE),0))) -> 0 | BO9: =IF($O9="Ya",BM9*BN9,0) -> 0 | BP9: =BM9+BO9 -> 0 | BQ9: =IF($L9="TER A",VLOOKUP(BM9,TER!$A$5:$D$48,4,TRUE),IF($L9="TER B",VLOOKUP(BM9,TER!$F$5:$I$44,4,TRUE),IF($L9="TER C",VLOOKUP(BM9,TER!$K$5:$N$45,4,TRUE),0))) -> 0 | BR9: =ROUND(BP9*BQ9,0) -> 0 | BT9: ='Data Gaji'!IL9 -> 0 | BU9: =IF($L9="TER A",VLOOKUP(BT9,TER!$A$5:$D$48,4,TRUE),IF($L9="TER B",VLOOKUP(BT9,TER!$F$5:$I$44,4,TRUE),IF($L9="TER C",VLOOKUP(BT9,TER!$K$5:$N$45,4,TRUE),0))) -> 0 | BV9: =IF($O9="Ya",BT9*BU9,0) -> 0 | BW9: =BT9+BV9 -> 0 | BX9: =IF($L9="TER A",VLOOKUP(BT9,TER!$A$5:$D$48,4,TRUE),IF($L9="TER B",VLOOKUP(BT9,TER!$F$5:$I$44,4,TRUE),IF($L9="TER C",VLOOKUP(BT9,TER!$K$5:$N$45,4,TRUE),0))) -> 0 | BY9: =ROUND(BW9*BX9,0) -> 0 | CA9: ='Data Gaji'!JL9 -> 0 | CB9: =IF($L9="TER A",VLOOKUP(CA9,TER!$A$5:$D$48,4,TRUE),IF($L9="TER B",VLOOKUP(CA9,TER!$F$5:$I$44,4,TRUE),IF($L9="TER C",VLOOKUP(CA9,TER!$K$5:$N$45,4,TRUE),0))) -> 0 | CC9: =IF($O9="Ya",CA9*CB9,0) -> 0 | CD9: =CA9+CC9 -> 0 | CE9: =IF($L9="TER A",VLOOKUP(CA9,TER!$A$5:$D$48,4,TRUE),IF($L9="TER B",VLOOKUP(CA9,TER!$F$5:$I$44,4,TRUE),IF($L9="TER C",VLOOKUP(CA9,TER!$K$5:$N$45,4,TRUE),0))) -> 0 | CF9: =ROUND(CD9*CE9,0) -> 0 | CH9: ='Data Gaji'!KL9 -> 0 | CI9: =IF($L9="TER A",VLOOKUP(CH9,TER!$A$5:$D$48,4,TRUE),IF($L9="TER B",VLOOKUP(CH9,TER!$F$5:$I$44,4,TRUE),IF($L9="TER C",VLOOKUP(CH9,TER!$K$5:$N$45,4,TRUE),0))) -> 0 | CJ9: =IF($O9="Ya",CH9*CI9,0) -> 0 | CK9: =CH9+CJ9 -> 0 | CL9: =IF($L9="TER A",VLOOKUP(CH9,TER!$A$5:$D$48,4,TRUE),IF($L9="TER B",VLOOKUP(CH9,TER!$F$5:$I$44,4,TRUE),IF($L9="TER C",VLOOKUP(CH9,TER!$K$5:$N$45,4,TRUE),0))) -> 0 | CM9: =ROUND(CK9*CL9,0) -> 0 | CO9: ='Data Gaji'!LL9 -> 0 | CP9: =IF($L9="TER A",VLOOKUP(CO9,TER!$A$5:$D$48,4,TRUE),IF($L9="TER B",VLOOKUP(CO9,TER!$F$5:$I$44,4,TRUE),IF($L9="TER C",VLOOKUP(CO9,TER!$K$5:$N$45,4,TRUE),0))) -> 0 | CQ9: =IF($O9="Ya",CO9*CP9,0) -> 0 | CR9: =CO9+CQ9 -> 0 | CS9: =IF($L9="TER A",VLOOKUP(CO9,TER!$A$5:$D$48,4,TRUE),IF($L9="TER B",VLOOKUP(CO9,TER!$F$5:$I$44,4,TRUE),IF($L9="TER C",VLOOKUP(CO9,TER!$K$5:$N$45,4,TRUE),0))) -> 0 | CT9: =CR9*CS9 -> 0
A10: =A9+1 -> 4 | K10: ='Data Gaji'!K10 -> 0 | L10: =IF(ISNA(VLOOKUP(K10,'PTKP & TARIF'!$D$4:$E$11,2,0)),"",VLOOKUP(K10,'PTKP & TARIF'!$D$4:$E$11,2,0)) | M10: 26 | N10: 26 | O10: TIDAK | P10: ='Data Gaji'!AL10 -> 0 | Q10: =IF($L10="TER A",VLOOKUP(P10,TER!$A$5:$D$48,4,TRUE),IF($L10="TER B",VLOOKUP(P10,TER!$F$5:$I$44,4,TRUE),IF($L10="TER C",VLOOKUP(P10,TER!$K$5:$N$45,4,TRUE),0))) -> 0 | R10: =IF($O10="Ya",P10*Q10,0) -> 0 | S10: =P10+R10 -> 0 | T10: =IF($L10="TER A",VLOOKUP(P10,TER!$A$5:$D$48,4,TRUE),IF($L10="TER B",VLOOKUP(P10,TER!$F$5:$I$44,4,TRUE),IF($L10="TER C",VLOOKUP(P10,TER!$K$5:$N$45,4,TRUE),0))) -> 0 | U10: =ROUND(S10*T10,0) -> 0 | W10: ='Data Gaji'!BL10 -> 0 | X10: =IF($L10="TER A",VLOOKUP(W10,TER!$A$5:$D$48,4,TRUE),IF($L10="TER B",VLOOKUP(W10,TER!$F$5:$I$44,4,TRUE),IF($L10="TER C",VLOOKUP(W10,TER!$K$5:$N$45,4,TRUE),0))) -> 0 | Y10: =IF($O10="Ya",W10*X10,0) -> 0 | Z10: =W10+Y10 -> 0 | AA10: =IF($L10="TER A",VLOOKUP(W10,TER!$A$5:$D$48,4,TRUE),IF($L10="TER B",VLOOKUP(W10,TER!$F$5:$I$44,4,TRUE),IF($L10="TER C",VLOOKUP(W10,TER!$K$5:$N$45,4,TRUE),0))) -> 0 | AB10: =ROUND(Z10*AA10,0) -> 0 | AD10: ='Data Gaji'!CL10 -> 0 | AE10: =IF($L10="TER A",VLOOKUP(AD10,TER!$A$5:$D$48,4,TRUE),IF($L10="TER B",VLOOKUP(AD10,TER!$F$5:$I$44,4,TRUE),IF($L10="TER C",VLOOKUP(AD10,TER!$K$5:$N$45,4,TRUE),0))) -> 0 | AF10: =IF($O10="Ya",AD10*AE10,0) -> 0 | AG10: =AD10+AF10 -> 0 | AH10: =IF($L10="TER A",VLOOKUP(AD10,TER!$A$5:$D$48,4,TRUE),IF($L10="TER B",VLOOKUP(AD10,TER!$F$5:$I$44,4,TRUE),IF($L10="TER C",VLOOKUP(AD10,TER!$K$5:$N$45,4,TRUE),0))) -> 0 | AI10: =ROUND(AG10*AH10,0) -> 0 | AK10: ='Data Gaji'!DL10 -> 0 | AL10: =IF($L10="TER A",VLOOKUP(AK10,TER!$A$5:$D$48,4,TRUE),IF($L10="TER B",VLOOKUP(AK10,TER!$F$5:$I$44,4,TRUE),IF($L10="TER C",VLOOKUP(AK10,TER!$K$5:$N$45,4,TRUE),0))) -> 0 | AM10: =IF($O10="Ya",AK10*AL10,0) -> 0 | AN10: =AK10+AM10 -> 0 | AO10: =IF($L10="TER A",VLOOKUP(AK10,TER!$A$5:$D$48,4,TRUE),IF($L10="TER B",VLOOKUP(AK10,TER!$F$5:$I$44,4,TRUE),IF($L10="TER C",VLOOKUP(AK10,TER!$K$5:$N$45,4,TRUE),0))) -> 0 | AP10: =ROUND(AN10*AO10,0) -> 0 | AR10: ='Data Gaji'!EL10 -> 0 | AS10: =IF($L10="TER A",VLOOKUP(AR10,TER!$A$5:$D$48,4,TRUE),IF($L10="TER B",VLOOKUP(AR10,TER!$F$5:$I$44,4,TRUE),IF($L10="TER C",VLOOKUP(AR10,TER!$K$5:$N$45,4,TRUE),0))) -> 0 | AT10: =IF($O10="Ya",AR10*AS10,0) -> 0 | AU10: =AR10+AT10 -> 0 | AV10: =IF($L10="TER A",VLOOKUP(AR10,TER!$A$5:$D$48,4,TRUE),IF($L10="TER B",VLOOKUP(AR10,TER!$F$5:$I$44,4,TRUE),IF($L10="TER C",VLOOKUP(AR10,TER!$K$5:$N$45,4,TRUE),0))) -> 0 | AW10: =ROUND(AU10*AV10,0) -> 0 | AY10: ='Data Gaji'!FL10 -> 0 | AZ10: =IF($L10="TER A",VLOOKUP(AY10,TER!$A$5:$D$48,4,TRUE),IF($L10="TER B",VLOOKUP(AY10,TER!$F$5:$I$44,4,TRUE),IF($L10="TER C",VLOOKUP(AY10,TER!$K$5:$N$45,4,TRUE),0))) -> 0 | BA10: =IF($O10="Ya",AY10*AZ10,0) -> 0 | BB10: =AY10+BA10 -> 0 | BC10: =IF($L10="TER A",VLOOKUP(AY10,TER!$A$5:$D$48,4,TRUE),IF($L10="TER B",VLOOKUP(AY10,TER!$F$5:$I$44,4,TRUE),IF($L10="TER C",VLOOKUP(AY10,TER!$K$5:$N$45,4,TRUE),0))) -> 0 | BD10: =ROUND(BB10*BC10,0) -> 0 | BF10: ='Data Gaji'!GL10 -> 0 | BG10: =IF($L10="TER A",VLOOKUP(BF10,TER!$A$5:$D$48,4,TRUE),IF($L10="TER B",VLOOKUP(BF10,TER!$F$5:$I$44,4,TRUE),IF($L10="TER C",VLOOKUP(BF10,TER!$K$5:$N$45,4,TRUE),0))) -> 0 | BH10: =IF($O10="Ya",BF10*BG10,0) -> 0 | BI10: =BF10+BH10 -> 0 | BJ10: =IF($L10="TER A",VLOOKUP(BF10,TER!$A$5:$D$48,4,TRUE),IF($L10="TER B",VLOOKUP(BF10,TER!$F$5:$I$44,4,TRUE),IF($L10="TER C",VLOOKUP(BF10,TER!$K$5:$N$45,4,TRUE),0))) -> 0 | BK10: =ROUND(BI10*BJ10,0) -> 0 | BM10: ='Data Gaji'!HL10 -> 0 | BN10: =IF($L10="TER A",VLOOKUP(BM10,TER!$A$5:$D$48,4,TRUE),IF($L10="TER B",VLOOKUP(BM10,TER!$F$5:$I$44,4,TRUE),IF($L10="TER C",VLOOKUP(BM10,TER!$K$5:$N$45,4,TRUE),0))) -> 0 | BO10: =IF($O10="Ya",BM10*BN10,0) -> 0 | BP10: =BM10+BO10 -> 0 | BQ10: =IF($L10="TER A",VLOOKUP(BM10,TER!$A$5:$D$48,4,TRUE),IF($L10="TER B",VLOOKUP(BM10,TER!$F$5:$I$44,4,TRUE),IF($L10="TER C",VLOOKUP(BM10,TER!$K$5:$N$45,4,TRUE),0))) -> 0 | BR10: =ROUND(BP10*BQ10,0) -> 0 | BT10: ='Data Gaji'!IL10 -> 0 | BU10: =IF($L10="TER A",VLOOKUP(BT10,TER!$A$5:$D$48,4,TRUE),IF($L10="TER B",VLOOKUP(BT10,TER!$F$5:$I$44,4,TRUE),IF($L10="TER C",VLOOKUP(BT10,TER!$K$5:$N$45,4,TRUE),0))) -> 0 | BV10: =IF($O10="Ya",BT10*BU10,0) -> 0 | BW10: =BT10+BV10 -> 0 | BX10: =IF($L10="TER A",VLOOKUP(BT10,TER!$A$5:$D$48,4,TRUE),IF($L10="TER B",VLOOKUP(BT10,TER!$F$5:$I$44,4,TRUE),IF($L10="TER C",VLOOKUP(BT10,TER!$K$5:$N$45,4,TRUE),0))) -> 0 | BY10: =ROUND(BW10*BX10,0) -> 0 | CA10: ='Data Gaji'!JL10 -> 0 | CB10: =IF($L10="TER A",VLOOKUP(CA10,TER!$A$5:$D$48,4,TRUE),IF($L10="TER B",VLOOKUP(CA10,TER!$F$5:$I$44,4,TRUE),IF($L10="TER C",VLOOKUP(CA10,TER!$K$5:$N$45,4,TRUE),0))) -> 0 | CC10: =IF($O10="Ya",CA10*CB10,0) -> 0 | CD10: =CA10+CC10 -> 0 | CE10: =IF($L10="TER A",VLOOKUP(CA10,TER!$A$5:$D$48,4,TRUE),IF($L10="TER B",VLOOKUP(CA10,TER!$F$5:$I$44,4,TRUE),IF($L10="TER C",VLOOKUP(CA10,TER!$K$5:$N$45,4,TRUE),0))) -> 0 | CF10: =ROUND(CD10*CE10,0) -> 0 | CH10: ='Data Gaji'!KL10 -> 0 | CI10: =IF($L10="TER A",VLOOKUP(CH10,TER!$A$5:$D$48,4,TRUE),IF($L10="TER B",VLOOKUP(CH10,TER!$F$5:$I$44,4,TRUE),IF($L10="TER C",VLOOKUP(CH10,TER!$K$5:$N$45,4,TRUE),0))) -> 0 | CJ10: =IF($O10="Ya",CH10*CI10,0) -> 0 | CK10: =CH10+CJ10 -> 0 | CL10: =IF($L10="TER A",VLOOKUP(CH10,TER!$A$5:$D$48,4,TRUE),IF($L10="TER B",VLOOKUP(CH10,TER!$F$5:$I$44,4,TRUE),IF($L10="TER C",VLOOKUP(CH10,TER!$K$5:$N$45,4,TRUE),0))) -> 0 | CM10: =ROUND(CK10*CL10,0) -> 0 | CO10: ='Data Gaji'!LL10 -> 0 | CP10: =IF($L10="TER A",VLOOKUP(CO10,TER!$A$5:$D$48,4,TRUE),IF($L10="TER B",VLOOKUP(CO10,TER!$F$5:$I$44,4,TRUE),IF($L10="TER C",VLOOKUP(CO10,TER!$K$5:$N$45,4,TRUE),0))) -> 0 | CQ10: =IF($O10="Ya",CO10*CP10,0) -> 0 | CR10: =CO10+CQ10 -> 0 | CS10: =IF($L10="TER A",VLOOKUP(CO10,TER!$A$5:$D$48,4,TRUE),IF($L10="TER B",VLOOKUP(CO10,TER!$F$5:$I$44,4,TRUE),IF($L10="TER C",VLOOKUP(CO10,TER!$K$5:$N$45,4,TRUE),0))) -> 0 | CT10: =CR10*CS10 -> 0
A11: =A10+1 -> 5 | K11: ='Data Gaji'!K11 -> 0 | L11: =IF(ISNA(VLOOKUP(K11,'PTKP & TARIF'!$D$4:$E$11,2,0)),"",VLOOKUP(K11,'PTKP & TARIF'!$D$4:$E$11,2,0)) | M11: 26 | N11: 26 | O11: TIDAK | P11: ='Data Gaji'!AL11 -> 0 | Q11: =IF($L11="TER A",VLOOKUP(P11,TER!$A$5:$D$48,4,TRUE),IF($L11="TER B",VLOOKUP(P11,TER!$F$5:$I$44,4,TRUE),IF($L11="TER C",VLOOKUP(P11,TER!$K$5:$N$45,4,TRUE),0))) -> 0 | R11: =IF($O11="Ya",P11*Q11,0) -> 0 | S11: =P11+R11 -> 0 | T11: =IF($L11="TER A",VLOOKUP(P11,TER!$A$5:$D$48,4,TRUE),IF($L11="TER B",VLOOKUP(P11,TER!$F$5:$I$44,4,TRUE),IF($L11="TER C",VLOOKUP(P11,TER!$K$5:$N$45,4,TRUE),0))) -> 0 | U11: =ROUND(S11*T11,0) -> 0 | W11: ='Data Gaji'!BL11 -> 0 | X11: =IF($L11="TER A",VLOOKUP(W11,TER!$A$5:$D$48,4,TRUE),IF($L11="TER B",VLOOKUP(W11,TER!$F$5:$I$44,4,TRUE),IF($L11="TER C",VLOOKUP(W11,TER!$K$5:$N$45,4,TRUE),0))) -> 0 | Y11: =IF($O11="Ya",W11*X11,0) -> 0 | Z11: =W11+Y11 -> 0 | AA11: =IF($L11="TER A",VLOOKUP(W11,TER!$A$5:$D$48,4,TRUE),IF($L11="TER B",VLOOKUP(W11,TER!$F$5:$I$44,4,TRUE),IF($L11="TER C",VLOOKUP(W11,TER!$K$5:$N$45,4,TRUE),0))) -> 0 | AB11: =ROUND(Z11*AA11,0) -> 0 | AD11: ='Data Gaji'!CL11 -> 0 | AE11: =IF($L11="TER A",VLOOKUP(AD11,TER!$A$5:$D$48,4,TRUE),IF($L11="TER B",VLOOKUP(AD11,TER!$F$5:$I$44,4,TRUE),IF($L11="TER C",VLOOKUP(AD11,TER!$K$5:$N$45,4,TRUE),0))) -> 0 | AF11: =IF($O11="Ya",AD11*AE11,0) -> 0 | AG11: =AD11+AF11 -> 0 | AH11: =IF($L11="TER A",VLOOKUP(AD11,TER!$A$5:$D$48,4,TRUE),IF($L11="TER B",VLOOKUP(AD11,TER!$F$5:$I$44,4,TRUE),IF($L11="TER C",VLOOKUP(AD11,TER!$K$5:$N$45,4,TRUE),0))) -> 0 | AI11: =ROUND(AG11*AH11,0) -> 0 | AK11: ='Data Gaji'!DL11 -> 0 | AL11: =IF($L11="TER A",VLOOKUP(AK11,TER!$A$5:$D$48,4,TRUE),IF($L11="TER B",VLOOKUP(AK11,TER!$F$5:$I$44,4,TRUE),IF($L11="TER C",VLOOKUP(AK11,TER!$K$5:$N$45,4,TRUE),0))) -> 0 | AM11: =IF($O11="Ya",AK11*AL11,0) -> 0 | AN11: =AK11+AM11 -> 0 | AO11: =IF($L11="TER A",VLOOKUP(AK11,TER!$A$5:$D$48,4,TRUE),IF($L11="TER B",VLOOKUP(AK11,TER!$F$5:$I$44,4,TRUE),IF($L11="TER C",VLOOKUP(AK11,TER!$K$5:$N$45,4,TRUE),0))) -> 0 | AP11: =ROUND(AN11*AO11,0) -> 0 | AR11: ='Data Gaji'!EL11 -> 0 | AS11: =IF($L11="TER A",VLOOKUP(AR11,TER!$A$5:$D$48,4,TRUE),IF($L11="TER B",VLOOKUP(AR11,TER!$F$5:$I$44,4,TRUE),IF($L11="TER C",VLOOKUP(AR11,TER!$K$5:$N$45,4,TRUE),0))) -> 0 | AT11: =IF($O11="Ya",AR11*AS11,0) -> 0 | AU11: =AR11+AT11 -> 0 | AV11: =IF($L11="TER A",VLOOKUP(AR11,TER!$A$5:$D$48,4,TRUE),IF($L11="TER B",VLOOKUP(AR11,TER!$F$5:$I$44,4,TRUE),IF($L11="TER C",VLOOKUP(AR11,TER!$K$5:$N$45,4,TRUE),0))) -> 0 | AW11: =ROUND(AU11*AV11,0) -> 0 | AY11: ='Data Gaji'!FL11 -> 0 | AZ11: =IF($L11="TER A",VLOOKUP(AY11,TER!$A$5:$D$48,4,TRUE),IF($L11="TER B",VLOOKUP(AY11,TER!$F$5:$I$44,4,TRUE),IF($L11="TER C",VLOOKUP(AY11,TER!$K$5:$N$45,4,TRUE),0))) -> 0 | BA11: =IF($O11="Ya",AY11*AZ11,0) -> 0 | BB11: =AY11+BA11 -> 0 | BC11: =IF($L11="TER A",VLOOKUP(AY11,TER!$A$5:$D$48,4,TRUE),IF($L11="TER B",VLOOKUP(AY11,TER!$F$5:$I$44,4,TRUE),IF($L11="TER C",VLOOKUP(AY11,TER!$K$5:$N$45,4,TRUE),0))) -> 0 | BD11: =ROUND(BB11*BC11,0) -> 0 | BF11: ='Data Gaji'!GL11 -> 0 | BG11: =IF($L11="TER A",VLOOKUP(BF11,TER!$A$5:$D$48,4,TRUE),IF($L11="TER B",VLOOKUP(BF11,TER!$F$5:$I$44,4,TRUE),IF($L11="TER C",VLOOKUP(BF11,TER!$K$5:$N$45,4,TRUE),0))) -> 0 | BH11: =IF($O11="Ya",BF11*BG11,0) -> 0 | BI11: =BF11+BH11 -> 0 | BJ11: =IF($L11="TER A",VLOOKUP(BF11,TER!$A$5:$D$48,4,TRUE),IF($L11="TER B",VLOOKUP(BF11,TER!$F$5:$I$44,4,TRUE),IF($L11="TER C",VLOOKUP(BF11,TER!$K$5:$N$45,4,TRUE),0))) -> 0 | BK11: =ROUND(BI11*BJ11,0) -> 0 | BM11: ='Data Gaji'!HL11 -> 0 | BN11: =IF($L11="TER A",VLOOKUP(BM11,TER!$A$5:$D$48,4,TRUE),IF($L11="TER B",VLOOKUP(BM11,TER!$F$5:$I$44,4,TRUE),IF($L11="TER C",VLOOKUP(BM11,TER!$K$5:$N$45,4,TRUE),0))) -> 0 | BO11: =IF($O11="Ya",BM11*BN11,0) -> 0 | BP11: =BM11+BO11 -> 0 | BQ11: =IF($L11="TER A",VLOOKUP(BM11,TER!$A$5:$D$48,4,TRUE),IF($L11="TER B",VLOOKUP(BM11,TER!$F$5:$I$44,4,TRUE),IF($L11="TER C",VLOOKUP(BM11,TER!$K$5:$N$45,4,TRUE),0))) -> 0 | BR11: =ROUND(BP11*BQ11,0) -> 0 | BT11: ='Data Gaji'!IL11 -> 0 | BU11: =IF($L11="TER A",VLOOKUP(BT11,TER!$A$5:$D$48,4,TRUE),IF($L11="TER B",VLOOKUP(BT11,TER!$F$5:$I$44,4,TRUE),IF($L11="TER C",VLOOKUP(BT11,TER!$K$5:$N$45,4,TRUE),0))) -> 0 | BV11: =IF($O11="Ya",BT11*BU11,0) -> 0 | BW11: =BT11+BV11 -> 0 | BX11: =IF($L11="TER A",VLOOKUP(BT11,TER!$A$5:$D$48,4,TRUE),IF($L11="TER B",VLOOKUP(BT11,TER!$F$5:$I$44,4,TRUE),IF($L11="TER C",VLOOKUP(BT11,TER!$K$5:$N$45,4,TRUE),0))) -> 0 | BY11: =ROUND(BW11*BX11,0) -> 0 | CA11: ='Data Gaji'!JL11 -> 0 | CB11: =IF($L11="TER A",VLOOKUP(CA11,TER!$A$5:$D$48,4,TRUE),IF($L11="TER B",VLOOKUP(CA11,TER!$F$5:$I$44,4,TRUE),IF($L11="TER C",VLOOKUP(CA11,TER!$K$5:$N$45,4,TRUE),0))) -> 0 | CC11: =IF($O11="Ya",CA11*CB11,0) -> 0 | CD11: =CA11+CC11 -> 0 | CE11: =IF($L11="TER A",VLOOKUP(CA11,TER!$A$5:$D$48,4,TRUE),IF($L11="TER B",VLOOKUP(CA11,TER!$F$5:$I$44,4,TRUE),IF($L11="TER C",VLOOKUP(CA11,TER!$K$5:$N$45,4,TRUE),0))) -> 0 | CF11: =ROUND(CD11*CE11,0) -> 0 | CH11: ='Data Gaji'!KL11 -> 0 | CI11: =IF($L11="TER A",VLOOKUP(CH11,TER!$A$5:$D$48,4,TRUE),IF($L11="TER B",VLOOKUP(CH11,TER!$F$5:$I$44,4,TRUE),IF($L11="TER C",VLOOKUP(CH11,TER!$K$5:$N$45,4,TRUE),0))) -> 0 | CJ11: =IF($O11="Ya",CH11*CI11,0) -> 0 | CK11: =CH11+CJ11 -> 0 | CL11: =IF($L11="TER A",VLOOKUP(CH11,TER!$A$5:$D$48,4,TRUE),IF($L11="TER B",VLOOKUP(CH11,TER!$F$5:$I$44,4,TRUE),IF($L11="TER C",VLOOKUP(CH11,TER!$K$5:$N$45,4,TRUE),0))) -> 0 | CM11: =ROUND(CK11*CL11,0) -> 0 | CO11: ='Data Gaji'!LL11 -> 0 | CP11: =IF($L11="TER A",VLOOKUP(CO11,TER!$A$5:$D$48,4,TRUE),IF($L11="TER B",VLOOKUP(CO11,TER!$F$5:$I$44,4,TRUE),IF($L11="TER C",VLOOKUP(CO11,TER!$K$5:$N$45,4,TRUE),0))) -> 0 | CQ11: =IF($O11="Ya",CO11*CP11,0) -> 0 | CR11: =CO11+CQ11 -> 0 | CS11: =IF($L11="TER A",VLOOKUP(CO11,TER!$A$5:$D$48,4,TRUE),IF($L11="TER B",VLOOKUP(CO11,TER!$F$5:$I$44,4,TRUE),IF($L11="TER C",VLOOKUP(CO11,TER!$K$5:$N$45,4,TRUE),0))) -> 0 | CT11: =CR11*CS11 -> 0
A12: =A11+1 -> 6 | K12: ='Data Gaji'!K12 -> 0 | L12: =IF(ISNA(VLOOKUP(K12,'PTKP & TARIF'!$D$4:$E$11,2,0)),"",VLOOKUP(K12,'PTKP & TARIF'!$D$4:$E$11,2,0)) | M12: 26 | N12: 26 | O12: TIDAK | P12: ='Data Gaji'!AL12 -> 0 | Q12: =IF($L12="TER A",VLOOKUP(P12,TER!$A$5:$D$48,4,TRUE),IF($L12="TER B",VLOOKUP(P12,TER!$F$5:$I$44,4,TRUE),IF($L12="TER C",VLOOKUP(P12,TER!$K$5:$N$45,4,TRUE),0))) -> 0 | R12: =IF($O12="Ya",P12*Q12,0) -> 0 | S12: =P12+R12 -> 0 | T12: =IF($L12="TER A",VLOOKUP(P12,TER!$A$5:$D$48,4,TRUE),IF($L12="TER B",VLOOKUP(P12,TER!$F$5:$I$44,4,TRUE),IF($L12="TER C",VLOOKUP(P12,TER!$K$5:$N$45,4,TRUE),0))) -> 0 | U12: =ROUND(S12*T12,0) -> 0 | W12: ='Data Gaji'!BL12 -> 0 | X12: =IF($L12="TER A",VLOOKUP(W12,TER!$A$5:$D$48,4,TRUE),IF($L12="TER B",VLOOKUP(W12,TER!$F$5:$I$44,4,TRUE),IF($L12="TER C",VLOOKUP(W12,TER!$K$5:$N$45,4,TRUE),0))) -> 0 | Y12: =IF($O12="Ya",W12*X12,0) -> 0 | Z12: =W12+Y12 -> 0 | AA12: =IF($L12="TER A",VLOOKUP(W12,TER!$A$5:$D$48,4,TRUE),IF($L12="TER B",VLOOKUP(W12,TER!$F$5:$I$44,4,TRUE),IF($L12="TER C",VLOOKUP(W12,TER!$K$5:$N$45,4,TRUE),0))) -> 0 | AB12: =ROUND(Z12*AA12,0) -> 0 | AD12: ='Data Gaji'!CL12 -> 0 | AE12: =IF($L12="TER A",VLOOKUP(AD12,TER!$A$5:$D$48,4,TRUE),IF($L12="TER B",VLOOKUP(AD12,TER!$F$5:$I$44,4,TRUE),IF($L12="TER C",VLOOKUP(AD12,TER!$K$5:$N$45,4,TRUE),0))) -> 0 | AF12: =IF($O12="Ya",AD12*AE12,0) -> 0 | AG12: =AD12+AF12 -> 0 | AH12: =IF($L12="TER A",VLOOKUP(AD12,TER!$A$5:$D$48,4,TRUE),IF($L12="TER B",VLOOKUP(AD12,TER!$F$5:$I$44,4,TRUE),IF($L12="TER C",VLOOKUP(AD12,TER!$K$5:$N$45,4,TRUE),0))) -> 0 | AI12: =ROUND(AG12*AH12,0) -> 0 | AK12: ='Data Gaji'!DL12 -> 0 | AL12: =IF($L12="TER A",VLOOKUP(AK12,TER!$A$5:$D$48,4,TRUE),IF($L12="TER B",VLOOKUP(AK12,TER!$F$5:$I$44,4,TRUE),IF($L12="TER C",VLOOKUP(AK12,TER!$K$5:$N$45,4,TRUE),0))) -> 0 | AM12: =IF($O12="Ya",AK12*AL12,0) -> 0 | AN12: =AK12+AM12 -> 0 | AO12: =IF($L12="TER A",VLOOKUP(AK12,TER!$A$5:$D$48,4,TRUE),IF($L12="TER B",VLOOKUP(AK12,TER!$F$5:$I$44,4,TRUE),IF($L12="TER C",VLOOKUP(AK12,TER!$K$5:$N$45,4,TRUE),0))) -> 0 | AP12: =ROUND(AN12*AO12,0) -> 0 | AR12: ='Data Gaji'!EL12 -> 0 | AS12: =IF($L12="TER A",VLOOKUP(AR12,TER!$A$5:$D$48,4,TRUE),IF($L12="TER B",VLOOKUP(AR12,TER!$F$5:$I$44,4,TRUE),IF($L12="TER C",VLOOKUP(AR12,TER!$K$5:$N$45,4,TRUE),0))) -> 0 | AT12: =IF($O12="Ya",AR12*AS12,0) -> 0 | AU12: =AR12+AT12 -> 0 | AV12: =IF($L12="TER A",VLOOKUP(AR12,TER!$A$5:$D$48,4,TRUE),IF($L12="TER B",VLOOKUP(AR12,TER!$F$5:$I$44,4,TRUE),IF($L12="TER C",VLOOKUP(AR12,TER!$K$5:$N$45,4,TRUE),0))) -> 0 | AW12: =ROUND(AU12*AV12,0) -> 0 | AY12: ='Data Gaji'!FL12 -> 0 | AZ12: =IF($L12="TER A",VLOOKUP(AY12,TER!$A$5:$D$48,4,TRUE),IF($L12="TER B",VLOOKUP(AY12,TER!$F$5:$I$44,4,TRUE),IF($L12="TER C",VLOOKUP(AY12,TER!$K$5:$N$45,4,TRUE),0))) -> 0 | BA12: =IF($O12="Ya",AY12*AZ12,0) -> 0 | BB12: =AY12+BA12 -> 0 | BC12: =IF($L12="TER A",VLOOKUP(AY12,TER!$A$5:$D$48,4,TRUE),IF($L12="TER B",VLOOKUP(AY12,TER!$F$5:$I$44,4,TRUE),IF($L12="TER C",VLOOKUP(AY12,TER!$K$5:$N$45,4,TRUE),0))) -> 0 | BD12: =ROUND(BB12*BC12,0) -> 0 | BF12: ='Data Gaji'!GL12 -> 0 | BG12: =IF($L12="TER A",VLOOKUP(BF12,TER!$A$5:$D$48,4,TRUE),IF($L12="TER B",VLOOKUP(BF12,TER!$F$5:$I$44,4,TRUE),IF($L12="TER C",VLOOKUP(BF12,TER!$K$5:$N$45,4,TRUE),0))) -> 0 | BH12: =IF($O12="Ya",BF12*BG12,0) -> 0 | BI12: =BF12+BH12 -> 0 | BJ12: =IF($L12="TER A",VLOOKUP(BF12,TER!$A$5:$D$48,4,TRUE),IF($L12="TER B",VLOOKUP(BF12,TER!$F$5:$I$44,4,TRUE),IF($L12="TER C",VLOOKUP(BF12,TER!$K$5:$N$45,4,TRUE),0))) -> 0 | BK12: =ROUND(BI12*BJ12,0) -> 0 | BM12: ='Data Gaji'!HL12 -> 0 | BN12: =IF($L12="TER A",VLOOKUP(BM12,TER!$A$5:$D$48,4,TRUE),IF($L12="TER B",VLOOKUP(BM12,TER!$F$5:$I$44,4,TRUE),IF($L12="TER C",VLOOKUP(BM12,TER!$K$5:$N$45,4,TRUE),0))) -> 0 | BO12: =IF($O12="Ya",BM12*BN12,0) -> 0 | BP12: =BM12+BO12 -> 0 | BQ12: =IF($L12="TER A",VLOOKUP(BM12,TER!$A$5:$D$48,4,TRUE),IF($L12="TER B",VLOOKUP(BM12,TER!$F$5:$I$44,4,TRUE),IF($L12="TER C",VLOOKUP(BM12,TER!$K$5:$N$45,4,TRUE),0))) -> 0 | BR12: =ROUND(BP12*BQ12,0) -> 0 | BT12: ='Data Gaji'!IL12 -> 0 | BU12: =IF($L12="TER A",VLOOKUP(BT12,TER!$A$5:$D$48,4,TRUE),IF($L12="TER B",VLOOKUP(BT12,TER!$F$5:$I$44,4,TRUE),IF($L12="TER C",VLOOKUP(BT12,TER!$K$5:$N$45,4,TRUE),0))) -> 0 | BV12: =IF($O12="Ya",BT12*BU12,0) -> 0 | BW12: =BT12+BV12 -> 0 | BX12: =IF($L12="TER A",VLOOKUP(BT12,TER!$A$5:$D$48,4,TRUE),IF($L12="TER B",VLOOKUP(BT12,TER!$F$5:$I$44,4,TRUE),IF($L12="TER C",VLOOKUP(BT12,TER!$K$5:$N$45,4,TRUE),0))) -> 0 | BY12: =ROUND(BW12*BX12,0) -> 0 | CA12: ='Data Gaji'!JL12 -> 0 | CB12: =IF($L12="TER A",VLOOKUP(CA12,TER!$A$5:$D$48,4,TRUE),IF($L12="TER B",VLOOKUP(CA12,TER!$F$5:$I$44,4,TRUE),IF($L12="TER C",VLOOKUP(CA12,TER!$K$5:$N$45,4,TRUE),0))) -> 0 | CC12: =IF($O12="Ya",CA12*CB12,0) -> 0 | CD12: =CA12+CC12 -> 0 | CE12: =IF($L12="TER A",VLOOKUP(CA12,TER!$A$5:$D$48,4,TRUE),IF($L12="TER B",VLOOKUP(CA12,TER!$F$5:$I$44,4,TRUE),IF($L12="TER C",VLOOKUP(CA12,TER!$K$5:$N$45,4,TRUE),0))) -> 0 | CF12: =ROUND(CD12*CE12,0) -> 0 | CH12: ='Data Gaji'!KL12 -> 0 | CI12: =IF($L12="TER A",VLOOKUP(CH12,TER!$A$5:$D$48,4,TRUE),IF($L12="TER B",VLOOKUP(CH12,TER!$F$5:$I$44,4,TRUE),IF($L12="TER C",VLOOKUP(CH12,TER!$K$5:$N$45,4,TRUE),0))) -> 0 | CJ12: =IF($O12="Ya",CH12*CI12,0) -> 0 | CK12: =CH12+CJ12 -> 0 | CL12: =IF($L12="TER A",VLOOKUP(CH12,TER!$A$5:$D$48,4,TRUE),IF($L12="TER B",VLOOKUP(CH12,TER!$F$5:$I$44,4,TRUE),IF($L12="TER C",VLOOKUP(CH12,TER!$K$5:$N$45,4,TRUE),0))) -> 0 | CM12: =ROUND(CK12*CL12,0) -> 0 | CO12: ='Data Gaji'!LL12 -> 0 | CP12: =IF($L12="TER A",VLOOKUP(CO12,TER!$A$5:$D$48,4,TRUE),IF($L12="TER B",VLOOKUP(CO12,TER!$F$5:$I$44,4,TRUE),IF($L12="TER C",VLOOKUP(CO12,TER!$K$5:$N$45,4,TRUE),0))) -> 0 | CQ12: =IF($O12="Ya",CO12*CP12,0) -> 0 | CR12: =CO12+CQ12 -> 0 | CS12: =IF($L12="TER A",VLOOKUP(CO12,TER!$A$5:$D$48,4,TRUE),IF($L12="TER B",VLOOKUP(CO12,TER!$F$5:$I$44,4,TRUE),IF($L12="TER C",VLOOKUP(CO12,TER!$K$5:$N$45,4,TRUE),0))) -> 0 | CT12: =CR12*CS12 -> 0
